Workbook

Sheet Assessment
A1: Req ID | B1: Source document | C1: Section | D1: Requirement (verbatim) | E1: Obligation level | F1: Topic | G1: Impact rating | H1: Rationale (specific to this process) | I1: Affected activities / deliverables | J1: Required changes / actions | K1: Evidence to produce | L1: Owner role | M1: Dependencies on other processes | N1: Effort (S/M/L) | O1: Notes / assumptions
A2: TR1-001 | B2: BSI TR-03183-1 v1.0.0 | C2: 3 Overview Cyber Resilience Act | D2: Manufacturers need to take responsibility for cybersecurity during the entire support period of the PwDE. | E2: MUST (equiv. 'need to') | F2: Lifecycle responsibility | G2: Medium | H2: Maintenance must carry cybersecurity responsibility for every delivered release until its support period ends - not just until acceptance or warranty end. | I2: Long-term maintenance of all supported release lines | J2: Plan PSIRT and engineering capacity per supported release line until its support end date. | K2: Support-period register per release; capacity plan | L2: Service Delivery Manager / PSIRT Lead | M2: Support periods from 1. Presale | N2: M
A3: TR1-002 | B3: BSI TR-03183-1 v1.0.0 | C3: 3.1 New Legislative Framework | D3: The framework obliges manufacturers to ensure that the PwDE fulfils the applicable legal requirements. | E3: MUST (equiv. 'obliges') | F3: CRA conformity - general | G3: Low | H3: The obligation continues after delivery for the whole support period (the NLF obliges manufacturers to ensure the product fulfils the applicable legal requirements). | I3: Post-market obligations | J3: Cover the obligation in the post-market process (monitoring, updates, reviews). | K3: Post-market records | L3: Product Security Officer / PSIRT Lead | M3: Inputs from 2. and 3. | N3: S
A4: TR1-003 | B4: BSI TR-03183-1 v1.0.0 | C4: 3.1 New Legislative Framework | D4: Manufacturers are free to choose any technical solution to meet these requirements. | E4: MAY (equiv. 'are free to') | F4: CRA conformity - general | G4: Nil | H4: Nil - no change needed in 5. Solution Maintenance (RUN). Handled in 2. Solution Development (Head of Engineering / Security Architect). | I4: None for this process | J4: No action in this process. | K4: n/a | L4: n/a | M4: Handled in 2. Solution Development | N4: n/a
A5: TR1-004 | B5: BSI TR-03183-1 v1.0.0 | C5: 3.2 Scope of the CRA | D5: Besides physical PwDEs, which are generally required to affix the CE mark, software commercially distributed on the European Market will now be subject to the CE mark, indicating that the requirements set out in the CRA are fulfilled. | E5: MUST (equiv. 'required') | F5: EU declaration of conformity / CE marking | G5: Low | H5: Conformity must be maintained across updates; a substantial modification requires a new assessment (commercially distributed software is now subject to CE marking). | I5: Change impact assessment of updates | J5: Assess each update for substantial modification and update the DoC where needed. | K5: Change impact assessment record | L5: CRA Compliance Manager | M5: Changes from 2./3. | N5: S
A6: TR1-005 | B6: BSI TR-03183-1 v1.0.0 | C6: 3.4 Timeline | D6: The reporting obligations (Article 14 CRA) for manufacturers to report actively exploited vulnerabilities and severe incidents will start on 11 September 2026. | E6: Applicability rule (no modal verb) | F6: CRA timeline - reporting obligations | G6: Critical | H6: Art. 14 reporting has applied since 11 Sep 2026 (today is 18 Oct 2026): the 24h / 72h / final-report procedure via the single reporting platform must already be operational - the most urgent CRA obligation for the business. | I6: Vulnerability handling / PSIRT procedures, service management | J6: Set up an interim reporting capability immediately: name reporters and deputies, register on the single reporting platform, prepare templates, define awareness criteria and a 24/7 escalation path; rehearse once. | K6: Reporting procedure (approved); platform registration; on-call roster; exercise record | L6: PSIRT Lead / Service Delivery Manager | M6: Needs SBOM and release data from 3. Integration/Build; feeds 4. Deployment (patch roll-out) | N6: L | O6: Applicability rule without a modal verb; registered because it decides when CRA obligations apply to our solutions. Today is 18 Oct 2026, so this obligation is already in force.
A7: TR1-006 | B7: BSI TR-03183-1 v1.0.0 | C7: 3.4 Timeline | D7: This applies also to PwDEs already placed on the European market. | E7: Applicability rule (no modal verb) | F7: CRA timeline - reporting obligations | G7: Critical | H7: Reporting covers the whole installed base, including solutions delivered years ago to airports and government customers - their versions, sites and contacts must be known to the PSIRT now. | I7: Vulnerability handling / PSIRT procedures, service management | J7: Build or complete the installed-base register for all delivered solutions still in operation and link it to the PSIRT reporting procedure. | K7: Installed-base register covering legacy deliveries | L7: PSIRT Lead / Service Delivery Manager | M7: Needs SBOM and release data from 3. Integration/Build; feeds 4. Deployment (patch roll-out) | N7: L | O7: Applicability rule without a modal verb; registered because it decides when CRA obligations apply to our solutions.
A8: TR1-007 | B8: BSI TR-03183-1 v1.0.0 | C8: 3.4 Timeline | D8: From 11 December 2027 onwards, all products with digital elements in scope of the CRA that are made available on the European Market after this date must adhere to all CRA requirements. | E8: MUST (equiv. 'must') | F8: CRA timeline | G8: Medium | H8: Updates delivered after 11 Dec 2027 must keep conformity; a substantial modification of an installed legacy solution brings it fully into CRA scope. | I8: Vulnerability handling / PSIRT procedures, service management | J8: Embed 'from 11 Dec 2027 all in-scope products made available must meet all CRA requirements' in the PSIRT / vulnerability-handling procedure and service-management tooling. | K8: Procedure document; tickets/records proving execution; periodic review record | L8: PSIRT Lead / Service Delivery Manager | M8: Needs SBOM and release data from 3. Integration/Build; feeds 4. Deployment (patch roll-out) | N8: M | O8: Assumption: today is 18 Oct 2026; reporting obligations already apply since 11 Sep 2026, all other obligations from 11 Dec 2027.
A9: TR1-008 | B9: BSI TR-03183-1 v1.0.0 | C9: 3.4 Timeline | D9: Obligations laid down in Article 14 apply to all products with digital elements that fall within the scope of this Regulation that have been placed on the market before 11 December 2027 (Article 69(3) CRA). | E9: Applicability rule (no modal verb) | F9: CRA timeline - legacy products | G9: High | H9: Legacy installations remain subject to Art. 14 reporting even if they never become CRA-conformant products. | I9: Vulnerability handling / PSIRT procedures, service management | J9: Embed 'Art. 14 obligations apply to all in-scope products placed on the market before 11 Dec 2027' in the PSIRT / vulnerability-handling procedure and service-management tooling. | K9: Procedure document; tickets/records proving execution; periodic review record | L9: PSIRT Lead / Service Delivery Manager | M9: Needs SBOM and release data from 3. Integration/Build; feeds 4. Deployment (patch roll-out) | N9: M | O9: Applicability rule without a modal verb; registered because it decides when CRA obligations apply to our solutions.
A10: TR1-009 | B10: BSI TR-03183-1 v1.0.0 | C10: 3.4 Timeline | D10: Products with digital elements that have been placed on the market before 11 December 2027 are only subject to the CRA, if those PwDEs have been subject to a substantial modification after 11 December 2027 (Article 69(2) CRA). | E10: Applicability rule (no modal verb) | F10: CRA timeline - substantial modification | G10: High | H10: Every change to a legacy installation must be screened for substantial modification; security updates and bug fixes usually are not, changes of type or purpose can be. | I10: Vulnerability handling / PSIRT procedures, service management | J10: Embed 'products placed on the market before 11 Dec 2027 fall under the CRA only after a substantial modification after that date' in the PSIRT / vulnerability-handling procedure and service-management tooling. | K10: Procedure document; tickets/records proving execution; periodic review record | L10: PSIRT Lead / Service Delivery Manager | M10: Needs SBOM and release data from 3. Integration/Build; feeds 4. Deployment (patch roll-out) | N10: M | O10: Applicability rule without a modal verb; registered because it decides when CRA obligations apply to our solutions.
A11: TR1-010 | B11: BSI TR-03183-1 v1.0.0 | C11: 3.4 Timeline | D11: The above mentioned Obligations laid down in Article 14 form an exception and apply to all products with digital elements that fall within the scope of this Regulation that have been placed on the market before 11 December 2027 (Article 69(3) CRA). | E11: Applicability rule (no modal verb) | F11: CRA timeline - legacy products | G11: Medium | H11: Restates that reporting duties apply to the legacy installed base regardless of substantial modification. | I11: Vulnerability handling / PSIRT procedures, service management | J11: Embed 'Art. 14 obligations are the exception that applies to all products placed before 11 Dec 2027' in the PSIRT / vulnerability-handling procedure and service-management tooling. | K11: Procedure document; tickets/records proving execution; periodic review record | L11: PSIRT Lead / Service Delivery Manager | M11: Needs SBOM and release data from 3. Integration/Build; feeds 4. Deployment (patch roll-out) | N11: M | O11: Applicability rule without a modal verb; registered because it decides when CRA obligations apply to our solutions.
A12: TR1-011 | B12: BSI TR-03183-1 v1.0.0 | C12: 3.4 Timeline | D12: Based on the NLF [3] a substantial modification is given if the type and purpose of a PwDE is changed in a way which was not foreseen in the initial risk assessment. | E12: Applicability rule (definition) | F12: CRA timeline - substantial modification | G12: High | H12: Each change to an installed solution needs a documented check against the initial risk assessment to decide whether it is a substantial modification. | I12: Vulnerability handling / PSIRT procedures, service management | J12: Add a substantial-modification check (type/purpose change vs. initial risk assessment) to change management for all installed solutions. | K12: Change impact / substantial-modification decision record | L12: PSIRT Lead / Service Delivery Manager | M12: Needs SBOM and release data from 3. Integration/Build; feeds 4. Deployment (patch roll-out) | N12: M | O12: Applicability rule without a modal verb; registered because it decides when CRA obligations apply to our solutions. The European Commission is preparing definitive guidance on substantial modification.
A13: TR1-012 | B13: BSI TR-03183-1 v1.0.0 | C13: 3.4 Timeline | D13: As such typical maintenance of a PwDE with security updates and bug fixes is usually not considered a substantial modification. | E13: Applicability rule (definition) | F13: CRA timeline - substantial modification | G13: Medium | H13: Routine security updates and bug fixes can be shipped to legacy installations without triggering full CRA applicability - keep them separate from feature changes. | I13: Vulnerability handling / PSIRT procedures, service management | J13: Embed 'security updates and bug fixes are usually not a substantial modification' in the PSIRT / vulnerability-handling procedure and service-management tooling. | K13: Procedure document; tickets/records proving execution; periodic review record | L13: PSIRT Lead / Service Delivery Manager | M13: Needs SBOM and release data from 3. Integration/Build; feeds 4. Deployment (patch roll-out) | N13: M | O13: Applicability rule without a modal verb; registered because it decides when CRA obligations apply to our solutions.
A14: TR1-013 | B14: BSI TR-03183-1 v1.0.0 | C14: 3.5 Concepts - Security by Design and by Default | D14: The CRA mandates that manufacturers integrate cybersecurity into the planning, design, development, and maintenance of products with digital elements from the outset. | E14: MUST (equiv. 'mandates') | F14: Secure development lifecycle | G14: Medium | H14: The obligation continues after delivery for the whole support period (integrate cybersecurity into planning, design, development and maintenance from the outset). | I14: Post-market obligations | J14: Cover the obligation in the post-market process (monitoring, updates, reviews). | K14: Post-market records | L14: Product Security Officer / PSIRT Lead | M14: Inputs from 2. and 3. | N14: M
A15: TR1-014 | B15: BSI TR-03183-1 v1.0.0 | C15: 3.5 Concepts - Security by Design and by Default | D15: It also requires PwDEs to be secure by default, meaning users should not need to take extra steps to ensure secure use out-of-the-box. | E15: MUST (equiv. 'requires') | F15: Secure by default | G15: Low | H15: The property must be maintained through updates and re-assessed when new threats appear (products must be secure by default without extra user steps). | I15: Updates; post-market review | J15: Check in regression and post-market reviews that updates do not weaken the property. | K15: Regression/security test results for updates | L15: PSIRT Lead / QA Lead | M15: Updates from 2. Development and 3. Integration/Build | N15: S
A16: TR1-015 | B16: BSI TR-03183-1 v1.0.0 | C16: 3.5 Concepts - Risk-based approach | D16: The essential cybersecurity requirements have to be implemented based on a cybersecurity risk assessment taking into account the intended purpose and reasonably foreseeable use of a product with digital elements. | E16: MUST (equiv. 'have to') | F16: Risk assessment - general | G16: Low | H16: Post-market events (new vulnerabilities, threats, changes) must update the risk assessment (implement the essential requirements based on a risk assessment considering intended purpose and foreseeable use). | I16: Risk-assessment updates | J16: Trigger risk-assessment updates from PSIRT cases and threat intelligence. | K16: Updated risk-assessment versions | L16: Product Security Officer | M16: Analysis by 2. Development | N16: S
A17: TR1-016 | B17: BSI TR-03183-1 v1.0.0 | C17: 3.5 Concepts - Risk-based approach | D17: This approach ensures that all cybersecurity risks relevant to the PwDE have to be addressed ensuring an appropriate level of cybersecurity. | E17: MUST (equiv. 'have to') | F17: Risk assessment - general | G17: Low | H17: Post-market events (new vulnerabilities, threats, changes) must update the risk assessment (all relevant cybersecurity risks have to be addressed). | I17: Risk-assessment updates | J17: Trigger risk-assessment updates from PSIRT cases and threat intelligence. | K17: Updated risk-assessment versions | L17: Product Security Officer | M17: Analysis by 2. Development | N17: S
A18: TR1-017 | B18: BSI TR-03183-1 v1.0.0 | C18: 3.5 Concepts - Lifecycle Responsibility | D18: Manufacturers are responsible for cybersecurity throughout the entire lifecycle of their PwDEs, not just until the point of sale. | E18: Responsibility (equiv. 'are responsible') | F18: Lifecycle responsibility | G18: Medium | H18: Responsibility continues after acceptance: maintenance must handle cybersecurity for every installed release until its support period ends. | I18: Long-term maintenance of all supported release lines | J18: Plan PSIRT and engineering capacity per supported release line until its support end date. | K18: Support-period register per release; capacity plan | L18: Service Delivery Manager / PSIRT Lead | M18: Support periods from 1. Presale | N18: M
A19: TR1-018 | B19: BSI TR-03183-1 v1.0.0 | C19: 3.5 Concepts - Lifecycle Responsibility | D19: This entails handling of vulnerabilities, including providing timely security updates or other mitigating measures when necessary, during use for a determined support period so that it reflects the length of time during which the PwDE is expected to be in use, with a minimum of five years unless the PwDE is usually used less than five years. | E19: MUST (part of the responsibility; 'entails') | F19: Support period | G19: High | H19: Vulnerability handling and timely security updates must be delivered for every release for the whole (possibly 10+ year) support period; capacity and funding must match. | I19: Long-term maintenance of all supported release lines | J19: Plan PSIRT and engineering capacity per supported release line until its support end date. | K19: Support-period register per release; capacity plan | L19: Service Delivery Manager / PSIRT Lead | M19: Support periods from 1. Presale | N19: M
A20: TR1-019 | B20: BSI TR-03183-1 v1.0.0 | C20: 3.5 Concepts - Transparency and Information for Users | D20: The CRA emphasizes transparency, requiring manufacturers to provide clear and comprehensible information about the security features, contact information for vulnerability reporting and update policies of their PwDEs. | E20: MUST (equiv. 'requiring') | F20: Transparency & user information | G20: Medium | H20: The information must be kept current, e.g. contact point, support end date, update instructions (provide clear information on security features, vulnerability contact and update policies). | I20: Updates of user information | J20: Re-issue the user information when contacts, support dates or instructions change. | K20: Document revision history | L20: Service Delivery Manager | M20: Changes from 2./3. | N20: M
A21: TR1-020 | B21: BSI TR-03183-1 v1.0.0 | C21: 3.6 Obligations of the manufacturer - Pre-Market Obligations | D21: [The manufacturer has several obligations before placing a product with digital elements (PwDE) on the market:] Ensure that PwDEs meet the essential cybersecurity requirements outlined in Annex I, which includes designing, developing, and producing PwDEs to achieve an appropriate level of cybersecurity. The level of cybersecurity is based on a cybersecurity risk assessment for each PwDE as well as an appropriate treatment of potential risks to an acceptable level, considering the intended purpose, reasonably foreseeable use, operational environment, and expected period of use. | E21: MUST (obligation; imperative) | F21: Essential requirements - general | G21: Low | H21: The property must be maintained through updates and re-assessed when new threats appear (ensure products meet Annex I based on a per-product risk assessment and treatment). | I21: Updates; post-market review | J21: Check in regression and post-market reviews that updates do not weaken the property. | K21: Regression/security test results for updates | L21: PSIRT Lead / QA Lead | M21: Updates from 2. Development and 3. Integration/Build | N21: S
A22: TR1-021 | B22: BSI TR-03183-1 v1.0.0 | C22: 3.6 Obligations of the manufacturer - Pre-Market Obligations | D22: [The manufacturer has several obligations before placing a product with digital elements (PwDE) on the market:] Apply due diligence when integrating third-party components, including open source software, to make sure the component is suitable to be integrated in the PwDE and that arising vulnerabilities can be adequately addressed. | E22: MUST (obligation; imperative) | F22: Third-party component due diligence | G22: Medium | H22: Third-party components must be monitored for vulnerabilities and support status, and upstream maintainers informed (apply due diligence when integrating third-party components including open source). | I22: Supplier vulnerability information; upstream reporting | J22: Monitor supplier advisories and end-of-life dates; report found vulnerabilities upstream and track responses. | K22: Supplier advisory log; upstream reports | L22: PSIRT Lead | M22: SBOM from 3. Integration/Build | N22: M
A23: TR1-022-a | B23: BSI TR-03183-1 v1.0.0 | C23: 3.6 Obligations of the manufacturer - Pre-Market Obligations | D23: [The manufacturer has several obligations before placing a product with digital elements (PwDE) on the market:] Draw up the technical documentation (Article 31 CRA) containing at least the information set out in Annex VII that demonstrates compliance with the essential cybersecurity requirements. This documentation includes information about the PwDE, its intended purpose, its design and development. | E23: MUST (obligation; imperative) | F23: Technical documentation | G23: Medium | H23: The technical documentation must be kept up to date with updates and post-market findings (draw up the technical documentation (Art. 31, Annex VII) demonstrating compliance). | I23: Technical documentation maintenance | J23: Update the technical file with each security update and risk-assessment update. | K23: Technical file revision history | L23: CRA Compliance Manager | M23: Changes from 2., 3. and 5. | N23: M
A24: TR1-022-b | B24: BSI TR-03183-1 v1.0.0 | C24: 3.6 Obligations of the manufacturer - Pre-Market Obligations | D24: [The manufacturer has several obligations before placing a product with digital elements (PwDE) on the market:] It must also include a cybersecurity risk assessment that identifies potential threats and vulnerabilities, assesses their impact, and outlines the measures taken to mitigate these risks […] | E24: MUST (equiv. 'must') | F24: Technical documentation | G24: Low | H24: The technical documentation must be kept up to date with updates and post-market findings (the technical documentation must include the cybersecurity risk assessment). | I24: Technical documentation maintenance | J24: Update the technical file with each security update and risk-assessment update. | K24: Technical file revision history | L24: CRA Compliance Manager | M24: Changes from 2., 3. and 5. | N24: S
A25: TR1-022-c | B25: BSI TR-03183-1 v1.0.0 | C25: 3.6 Obligations of the manufacturer - Pre-Market Obligations | D25: [The manufacturer has several obligations before placing a product with digital elements (PwDE) on the market:] It must also include […] as well as a Software Bill of Material (SBOM). | E25: MUST (equiv. 'must') | F25: Technical documentation - SBOM | G25: Medium | H25: The technical documentation must be kept up to date with updates and post-market findings (the technical documentation must include an SBOM). | I25: Technical documentation maintenance | J25: Update the technical file with each security update and risk-assessment update. | K25: Technical file revision history | L25: CRA Compliance Manager | M25: Changes from 2., 3. and 5. | N25: M
... A32: TR1-027 | B32: BSI TR-03183-1 v1.0.0 | C32: 3.6 Obligations of the manufacturer - PwDE Monitoring and Post-Market Obligations | D32: This review includes updating the risk assessment as needed and addressing new risks appropriately. | E32: MUST (part of the review duty; 'includes') | F32: Post-market review | G32: High | H32: Post-market reviews must update the risk assessment and treat new risks; triggers and owners are needed. | I32: Post-market monitoring and vulnerability handling | J32: Operate SBOM-based continuous vulnerability monitoring, periodic security reviews and remediation for all supported releases. | K32: Monitoring records; review minutes; remediation tickets | L32: PSIRT Lead / Product Security Officer | M32: SBOMs from 3.; fixes from 2.; roll-out by 4. | N32: M
A33: TR1-028-a | B33: BSI TR-03183-1 v1.0.0 | C33: 3.6 Obligations of the manufacturer - PwDE Monitoring and Post-Market Obligations | D33: Additionally, the manufacturer ought to monitor the PwDE for vulnerabilities throughout its defined support period […] | E33: MUST (equiv. 'ought to') | F33: Vulnerability monitoring | G33: Critical | H33: Continuous vulnerability monitoring of every supported release (SBOM-based, incl. third-party components) for the full support period is a new capability and a CRA core duty. | I33: Post-market monitoring and vulnerability handling | J33: Operate SBOM-based continuous vulnerability monitoring, periodic security reviews and remediation for all supported releases. | K33: Monitoring records; review minutes; remediation tickets | L33: PSIRT Lead / Product Security Officer | M33: SBOMs from 3.; fixes from 2.; roll-out by 4. | N33: L | O33: The wording 'ought to' is advisory, but it restates the mandatory CRA duty to handle vulnerabilities during the support period.
A34: TR1-028-b | B34: BSI TR-03183-1 v1.0.0 | C34: 3.6 Obligations of the manufacturer - PwDE Monitoring and Post-Market Obligations | D34: […] and address found vulnerabilities appropriately, including by providing security updates […] | E34: MUST (equiv. 'ought to') | F34: Vulnerability remediation | G34: Critical | H34: Found vulnerabilities must be remediated with security updates for all supported releases - a remediation chain across engineering, build and field service. | I34: Post-market monitoring and vulnerability handling | J34: Operate SBOM-based continuous vulnerability monitoring, periodic security reviews and remediation for all supported releases. | K34: Monitoring records; review minutes; remediation tickets | L34: PSIRT Lead / Product Security Officer | M34: SBOMs from 3.; fixes from 2.; roll-out by 4. | N34: L | O34: The wording 'ought to' is advisory, but it restates the mandatory CRA duty to handle vulnerabilities during the support period.
A35: TR1-028-c | B35: BSI TR-03183-1 v1.0.0 | C35: 3.6 Obligations of the manufacturer - PwDE Monitoring and Post-Market Obligations | D35: […] generally free of charge unless otherwise agreed between a manufacturer and a business user in relation to a tailor-made product with digital elements. | E35: MUST (equiv. 'ought to') | F35: Security updates - free of charge | G35: High | H35: Security fixes must be delivered separately from paid feature upgrades so they can be provided free of charge. | I35: Post-market monitoring and vulnerability handling | J35: Operate SBOM-based continuous vulnerability monitoring, periodic security reviews and remediation for all supported releases. | K35: Monitoring records; review minutes; remediation tickets | L35: PSIRT Lead / Product Security Officer | M35: SBOMs from 3.; fixes from 2.; roll-out by 4. | N35: M | O35: The wording 'ought to' is advisory, but it restates the mandatory CRA duty to handle vulnerabilities during the support period. Assumption: many airport/government solutions are tailor-made for business users, so an explicit contractual agreement is possible but must be made deliberately.
A36: TR1-029 | B36: BSI TR-03183-1 v1.0.0 | C36: 3.6 Obligations of the manufacturer - PwDE Monitoring and Post-Market Obligations | D36: These post-market obligations have to be upheld during the support period of the PwDE determined by the manufacturer in accordance with the expected duration of use of the PwDE. | E36: MUST (equiv. 'have to') | F36: Support period | G36: High | H36: All post-market duties (monitoring, updates, reviews) must be upheld for the support period determined per solution. | I36: Long-term maintenance of all supported release lines | J36: Plan PSIRT and engineering capacity per supported release line until its support end date. | K36: Support-period register per release; capacity plan | L36: Service Delivery Manager / PSIRT Lead | M36: Support periods from 1. Presale | N36: M
A37: TR1-030 | B37: BSI TR-03183-1 v1.0.0 | C37: 3.6 Obligations of the manufacturer - PwDE Monitoring and Post-Market Obligations | D37: Generally, the support period is at least five years unless not appropriate for the type of PwDE and its foreseeable duration of use. | E37: Rule (equiv. 'is at least') | F37: Support period | G37: Medium | H37: the support period is generally at least five years - vulnerability handling and security updates must be resourced for the full support period of every delivered release. | I37: Long-term maintenance of all supported release lines | J37: Plan PSIRT and engineering capacity per supported release line until its support end date. | K37: Support-period register per release; capacity plan | L37: Service Delivery Manager / PSIRT Lead | M37: Support periods from 1. Presale | N37: M
A38: TR1-031-a | B38: BSI TR-03183-1 v1.0.0 | C38: 3.6 Obligations of the manufacturer - PwDE Monitoring and Post-Market Obligations | D38: In addition to that the manufacturer has to ensure that security updates […] are available for at least 10 years after the PwDE has been placed on the market or for the full support period, whichever is longer. | E38: MUST (equiv. 'has to') | F38: Availability of security updates | G38: High | H38: Security updates must stay available for at least 10 years after placing on the market (or the support period if longer) - a long-term update repository is needed. | I38: Long-term maintenance of all supported release lines | J38: Plan PSIRT and engineering capacity per supported release line until its support end date. | K38: Support-period register per release; capacity plan | L38: Service Delivery Manager / PSIRT Lead | M38: Support periods from 1. Presale | N38: M
A39: TR1-031-b | B39: BSI TR-03183-1 v1.0.0 | C39: 3.6 Obligations of the manufacturer - PwDE Monitoring and Post-Market Obligations | D39: In addition to that the manufacturer has to ensure that […] the technical documentation are available for at least 10 years after the PwDE has been placed on the market or for the full support period, whichever is longer. | E39: MUST (equiv. 'has to') | F39: Records retention | G39: Low | H39: The technical documentation must be kept up to date with updates and post-market findings (keep technical documentation available for at least 10 years (or the support period if longer)). | I39: Technical documentation maintenance | J39: Update the technical file with each security update and risk-assessment update. | K39: Technical file revision history | L39: CRA Compliance Manager | M39: Changes from 2., 3. and 5. | N39: S
A40: TR1-032-a | B40: BSI TR-03183-1 v1.0.0 | C40: 3.6 Obligations of the manufacturer - Reporting obligations | D40: Manufacturers have to report actively exploited vulnerabilities of the PwDE […] upon becoming aware of them. | E40: MUST (equiv. 'have to') | F40: CRA Art. 14 reporting - vulnerabilities | G40: Critical | H40: Reporting actively exploited vulnerabilities to CSIRT/ENISA is mandatory since 11 Sep 2026, also for solutions already installed at airports and government sites; it needs a 24/7-capable detection-to-notification procedure. | I40: CRA Art. 14 reporting procedure (ENISA single reporting platform, CSIRT) | J40: Implement the reporting procedure: awareness criteria, 24h / 72h / 14-day (vulnerability) and 24h / 72h / one-month (incident) timelines, platform accounts, templates, approvals and 24/7 escalation; rehearse it. | K40: Reporting procedure; platform registration; submitted reports; exercise records | L40: PSIRT Lead / Compliance Officer | M40: Facts from 2. Development; installed base from 4. Deployment | N40: L | O40: Reporting obligations apply since 11 Sep 2026 (today: 18 Oct 2026) and cover products placed on the market before 11 Dec 2027.
A41: TR1-032-b | B41: BSI TR-03183-1 v1.0.0 | C41: 3.6 Obligations of the manufacturer - Reporting obligations | D41: Manufacturers have to report […] severe cybersecurity incidents negatively affecting the security of products with digital elements upon becoming aware of them. | E41: MUST (equiv. 'have to') | F41: CRA Art. 14 reporting - incidents | G41: Critical | H41: Severe incidents affecting the security of our solutions (incl. remote data processing we operate) must be reported since 11 Sep 2026; needs incident classification criteria and the reporting procedure. | I41: CRA Art. 14 reporting procedure (ENISA single reporting platform, CSIRT) | J41: Implement the reporting procedure: awareness criteria, 24h / 72h / 14-day (vulnerability) and 24h / 72h / one-month (incident) timelines, platform accounts, templates, approvals and 24/7 escalation; rehearse it. | K41: Reporting procedure; platform registration; submitted reports; exercise records | L41: PSIRT Lead / Compliance Officer | M41: Facts from 2. Development; installed base from 4. Deployment | N41: L | O41: Reporting obligations apply since 11 Sep 2026 (today: 18 Oct 2026) and cover products placed on the market before 11 Dec 2027.
A42: TR1-033 | B42: BSI TR-03183-1 v1.0.0 | C42: 3.6 Obligations of the manufacturer - Reporting obligations | D42: Notifications must be made simultaneously to the CSIRT (Computer Security Incident Response Team) designated as coordinator and ENISA (European Union Agency for Cybersecurity) via the single reporting platform to be established under CRA Article 16. | E42: MUST | F42: CRA Art. 14 reporting - channel | G42: Critical | H42: Notifications go simultaneously to the coordinating CSIRT and ENISA via the single reporting platform - registration, accounts, roles and templates must be ready. | I42: CRA Art. 14 reporting procedure (ENISA single reporting platform, CSIRT) | J42: Implement the reporting procedure: awareness criteria, 24h / 72h / 14-day (vulnerability) and 24h / 72h / one-month (incident) timelines, platform accounts, templates, approvals and 24/7 escalation; rehearse it. | K42: Reporting procedure; platform registration; submitted reports; exercise records | L42: PSIRT Lead / Compliance Officer | M42: Facts from 2. Development; installed base from 4. Deployment | N42: L | O42: Reporting obligations apply since 11 Sep 2026 (today: 18 Oct 2026) and cover products placed on the market before 11 Dec 2027.
A43: TR1-034-a | B43: BSI TR-03183-1 v1.0.0 | C43: 3.6 Obligations of the manufacturer - Reporting obligations | D43: [The following notification timelines and content are given for actively exploited vulnerabilities:] Early Warning Notification: Must be submitted without undue delay and in any case within 24 hours of becoming aware of an actively exploited vulnerability […] | E43: MUST | F43: CRA Art. 14 reporting - vulnerabilities | G43: Critical | H43: An early warning within 24 hours of awareness needs on-call staff, pre-approved templates and a decision path that works on weekends. | I43: CRA Art. 14 reporting procedure (ENISA single reporting platform, CSIRT) | J43: Implement the reporting procedure: awareness criteria, 24h / 72h / 14-day (vulnerability) and 24h / 72h / one-month (incident) timelines, platform accounts, templates, approvals and 24/7 escalation; rehearse it. | K43: Reporting procedure; platform registration; submitted reports; exercise records | L43: PSIRT Lead / Compliance Officer | M43: Facts from 2. Development; installed base from 4. Deployment | N43: L | O43: Reporting obligations apply since 11 Sep 2026 (today: 18 Oct 2026) and cover products placed on the market before 11 Dec 2027.
A44: TR1-034-b | B44: BSI TR-03183-1 v1.0.0 | C44: 3.6 Obligations of the manufacturer - Reporting obligations | D44: [The following notification timelines and content are given for actively exploited vulnerabilities:] […] and should indicate, where applicable, the Member States where the PwDE has been made available of which the manufacturer is aware. | E44: SHOULD (equiv. 'should') | F44: CRA Art. 14 reporting - vulnerabilities | G44: High | H44: Early warnings should name the Member States where the solution is available - installed-base data must be retrievable on demand. | I44: CRA Art. 14 reporting procedure (ENISA single reporting platform, CSIRT) | J44: Implement the reporting procedure: awareness criteria, 24h / 72h / 14-day (vulnerability) and 24h / 72h / one-month (incident) timelines, platform accounts, templates, approvals and 24/7 escalation; rehearse it. | K44: Reporting procedure; platform registration; submitted reports; exercise records | L44: PSIRT Lead / Compliance Officer | M44: Facts from 2. Development; installed base from 4. Deployment | N44: M | O44: Reporting obligations apply since 11 Sep 2026 (today: 18 Oct 2026) and cover products placed on the market before 11 Dec 2027.
A45: TR1-035 | B45: BSI TR-03183-1 v1.0.0 | C45: 3.6 Obligations of the manufacturer - Reporting obligations | D45: [The following notification timelines and content are given for actively exploited vulnerabilities:] Vulnerability Notification: If not already provided, a more detailed notification must be submitted within 72 hours after becoming aware of an actively exploited vulnerability. | E45: MUST | F45: CRA Art. 14 reporting - vulnerabilities | G45: Critical | H45: A detailed vulnerability notification within 72 hours requires fast technical analysis and approval. | I45: CRA Art. 14 reporting procedure (ENISA single reporting platform, CSIRT) | J45: Implement the reporting procedure: awareness criteria, 24h / 72h / 14-day (vulnerability) and 24h / 72h / one-month (incident) timelines, platform accounts, templates, approvals and 24/7 escalation; rehearse it. | K45: Reporting procedure; platform registration; submitted reports; exercise records | L45: PSIRT Lead / Compliance Officer | M45: Facts from 2. Development; installed base from 4. Deployment | N45: L | O45: Reporting obligations apply since 11 Sep 2026 (today: 18 Oct 2026) and cover products placed on the market before 11 Dec 2027.
A46: TR1-036 | B46: BSI TR-03183-1 v1.0.0 | C46: 3.6 Obligations of the manufacturer - Reporting obligations | D46: [The following notification timelines and content are given for actively exploited vulnerabilities:] This should include general information about the PwDE, as available, the general nature of the exploit and vulnerability, corrective or mitigating actions taken, and guidance for users. | E46: SHOULD (equiv. 'should') | F46: CRA Art. 14 reporting - vulnerabilities | G46: High | H46: The 72-hour notification content (product information, nature of the exploit, mitigations, user guidance) needs templates and engineering input. | I46: CRA Art. 14 reporting procedure (ENISA single reporting platform, CSIRT) | J46: Implement the reporting procedure: awareness criteria, 24h / 72h / 14-day (vulnerability) and 24h / 72h / one-month (incident) timelines, platform accounts, templates, approvals and 24/7 escalation; rehearse it. | K46: Reporting procedure; platform registration; submitted reports; exercise records | L46: PSIRT Lead / Compliance Officer | M46: Facts from 2. Development; installed base from 4. Deployment | N46: M | O46: Reporting obligations apply since 11 Sep 2026 (today: 18 Oct 2026) and cover products placed on the market before 11 Dec 2027.
...

Sheet Summary
A1: CRA / BSI TR-03183 impact summary - 5. Solution Maintenance (RUN) | X1: helper: listed row | Y1: helper: Critical rows | Z1: helper: High rows
A2: Role: solution provider acting as CRA manufacturer; default-category solutions for governments and airports. Assessment date 18 Oct 2026. | Y2: =IF(Assessment!$G2="Critical",ROW(Assessment!$G2),"") | Z2: =IF(Assessment!$G2="High",ROW(Assessment!$G2),"")
A3: All counts are COUNTIF / COUNTIFS formulas on the Assessment sheet and update when a rating is changed there. | Y3: =IF(Assessment!$G3="Critical",ROW(Assessment!$G3),"") | Z3: =IF(Assessment!$G3="High",ROW(Assessment!$G3),"")
Y4: =IF(Assessment!$G4="Critical",ROW(Assessment!$G4),"") | Z4: =IF(Assessment!$G4="High",ROW(Assessment!$G4),"")
A5: Impact rating | B5: All documents | C5: BSI TR-03183-1 v1.0.0 | D5: BSI TR-03183-2 v2.1.0 | E5: BSI TR-03183-3 v1.0.0 | F5: Share of all requirements | Y5: =IF(Assessment!$G5="Critical",ROW(Assessment!$G5),"") | Z5: =IF(Assessment!$G5="High",ROW(Assessment!$G5),"")
A6: Critical | B6: =COUNTIF(Assessment!$G:$G,$A6) -> 26 | C6: =COUNTIFS(Assessment!$B:$B,C$5,Assessment!$G:$G,$A6) -> 20 | D6: =COUNTIFS(Assessment!$B:$B,D$5,Assessment!$G:$G,$A6) -> 1 | E6: =COUNTIFS(Assessment!$B:$B,E$5,Assessment!$G:$G,$A6) -> 5 | F6: =IF($B$11=0,0,B6/$B$11) -> 0.043918919 | Y6: =IF(Assessment!$G6="Critical",ROW(Assessment!$G6),"") -> 6 | Z6: =IF(Assessment!$G6="High",ROW(Assessment!$G6),"")
A7: High | B7: =COUNTIF(Assessment!$G:$G,$A7) -> 63 | C7: =COUNTIFS(Assessment!$B:$B,C$5,Assessment!$G:$G,$A7) -> 34 | D7: =COUNTIFS(Assessment!$B:$B,D$5,Assessment!$G:$G,$A7) -> 6 | E7: =COUNTIFS(Assessment!$B:$B,E$5,Assessment!$G:$G,$A7) -> 23 | F7: =IF($B$11=0,0,B7/$B$11) -> 0.10641892 | Y7: =IF(Assessment!$G7="Critical",ROW(Assessment!$G7),"") -> 7 | Z7: =IF(Assessment!$G7="High",ROW(Assessment!$G7),"")
A8: Medium | B8: =COUNTIF(Assessment!$G:$G,$A8) -> 119 | C8: =COUNTIFS(Assessment!$B:$B,C$5,Assessment!$G:$G,$A8) -> 51 | D8: =COUNTIFS(Assessment!$B:$B,D$5,Assessment!$G:$G,$A8) -> 14 | E8: =COUNTIFS(Assessment!$B:$B,E$5,Assessment!$G:$G,$A8) -> 54 | F8: =IF($B$11=0,0,B8/$B$11) -> 0.20101351 | Y8: =IF(Assessment!$G8="Critical",ROW(Assessment!$G8),"") | Z8: =IF(Assessment!$G8="High",ROW(Assessment!$G8),"")
A9: Low | B9: =COUNTIF(Assessment!$G:$G,$A9) -> 169 | C9: =COUNTIFS(Assessment!$B:$B,C$5,Assessment!$G:$G,$A9) -> 49 | D9: =COUNTIFS(Assessment!$B:$B,D$5,Assessment!$G:$G,$A9) -> 20 | E9: =COUNTIFS(Assessment!$B:$B,E$5,Assessment!$G:$G,$A9) -> 100 | F9: =IF($B$11=0,0,B9/$B$11) -> 0.28547297 | Y9: =IF(Assessment!$G9="Critical",ROW(Assessment!$G9),"") | Z9: =IF(Assessment!$G9="High",ROW(Assessment!$G9),"") -> 9
A10: Nil | B10: =COUNTIF(Assessment!$G:$G,$A10) -> 215 | C10: =COUNTIFS(Assessment!$B:$B,C$5,Assessment!$G:$G,$A10) -> 128 | D10: =COUNTIFS(Assessment!$B:$B,D$5,Assessment!$G:$G,$A10) -> 87 | E10: =COUNTIFS(Assessment!$B:$B,E$5,Assessment!$G:$G,$A10) -> 0 | F10: =IF($B$11=0,0,B10/$B$11) -> 0.36317568 | Y10: =IF(Assessment!$G10="Critical",ROW(Assessment!$G10),"") | Z10: =IF(Assessment!$G10="High",ROW(Assessment!$G10),"") -> 10
A11: Total | B11: =SUM(B6:B10) -> 592 | C11: =SUM(C6:C10) -> 282 | D11: =SUM(D6:D10) -> 128 | E11: =SUM(E6:E10) -> 182 | Y11: =IF(Assessment!$G11="Critical",ROW(Assessment!$G11),"") | Z11: =IF(Assessment!$G11="High",ROW(Assessment!$G11),"")
A12: Requirements in register | B12: =COUNTA(Assessment!$A:$A)-1 -> 592 | C12: =COUNTIF(Assessment!$B:$B,C$5) -> 282 | D12: =COUNTIF(Assessment!$B:$B,D$5) -> 128 | E12: =COUNTIF(Assessment!$B:$B,E$5) -> 182 | Y12: =IF(Assessment!$G12="Critical",ROW(Assessment!$G12),"") | Z12: =IF(Assessment!$G12="High",ROW(Assessment!$G12),"") -> 12
A13: Check: total = register | B13: =IF(B11=B12,"OK","CHECK") -> OK | C13: =IF(C11=C12,"OK","CHECK") -> OK | D13: =IF(D11=D12,"OK","CHECK") -> OK | E13: =IF(E11=E12,"OK","CHECK") -> OK | Y13: =IF(Assessment!$G13="Critical",ROW(Assessment!$G13),"") | Z13: =IF(Assessment!$G13="High",ROW(Assessment!$G13),"")
Y14: =IF(Assessment!$G14="Critical",ROW(Assessment!$G14),"") | Z14: =IF(Assessment!$G14="High",ROW(Assessment!$G14),"")
A15: Critical and High items (formula-driven: Critical first, then High, each in register order) | Y15: =IF(Assessment!$G15="Critical",ROW(Assessment!$G15),"") | Z15: =IF(Assessment!$G15="High",ROW(Assessment!$G15),"")
A16: # | B16: Req ID | C16: Source document | D16: Section | E16: Topic | F16: Impact rating | G16: Required changes / actions | H16: Owner role | I16: Effort (S/M/L) | Y16: =IF(Assessment!$G16="Critical",ROW(Assessment!$G16),"") | Z16: =IF(Assessment!$G16="High",ROW(Assessment!$G16),"")
A17: =IF($X17="","",1) -> 1 | B17: =IF($X17="","",INDEX(Assessment!$A:$A,$X17)) -> TR1-005 | C17: =IF($X17="","",INDEX(Assessment!$B:$B,$X17)) -> BSI TR-03183-1 v1.0.0 | D17: =IF($X17="","",INDEX(Assessment!$C:$C,$X17)) -> 3.4 Timeline | E17: =IF($X17="","",INDEX(Assessment!$F:$F,$X17)) -> CRA timeline - reporting obligations | F17: =IF($X17="","",INDEX(Assessment!$G:$G,$X17)) -> Critical | G17: =IF($X17="","",INDEX(Assessment!$J:$J,$X17)) -> Set up an interim reporting capability immediately: name reporters and deputies, register on the single reporting platform, prepare templates, define awareness criteria and a 24/7 escalation path; rehearse once. | H17: =IF($X17="","",INDEX(Assessment!$L:$L,$X17)) -> PSIRT Lead / Service Delivery Manager | I17: =IF($X17="","",INDEX(Assessment!$N:$N,$X17)) -> L | X17: =IF(1<=$B$6,SMALL($Y$2:$Y$593,1),IF(1<=$B$6+$B$7,SMALL($Z$2:$Z$593,1-$B$6),"")) -> 6 | Y17: =IF(Assessment!$G17="Critical",ROW(Assessment!$G17),"") | Z17: =IF(Assessment!$G17="High",ROW(Assessment!$G17),"")
A18: =IF($X18="","",2) -> 2 | B18: =IF($X18="","",INDEX(Assessment!$A:$A,$X18)) -> TR1-006 | C18: =IF($X18="","",INDEX(Assessment!$B:$B,$X18)) -> BSI TR-03183-1 v1.0.0 | D18: =IF($X18="","",INDEX(Assessment!$C:$C,$X18)) -> 3.4 Timeline | E18: =IF($X18="","",INDEX(Assessment!$F:$F,$X18)) -> CRA timeline - reporting obligations | F18: =IF($X18="","",INDEX(Assessment!$G:$G,$X18)) -> Critical | G18: =IF($X18="","",INDEX(Assessment!$J:$J,$X18)) -> Build or complete the installed-base register for all delivered solutions still in operation and link it to the PSIRT reporting procedure. | H18: =IF($X18="","",INDEX(Assessment!$L:$L,$X18)) -> PSIRT Lead / Service Delivery Manager | I18: =IF($X18="","",INDEX(Assessment!$N:$N,$X18)) -> L | X18: =IF(2<=$B$6,SMALL($Y$2:$Y$593,2),IF(2<=$B$6+$B$7,SMALL($Z$2:$Z$593,2-$B$6),"")) -> 7 | Y18: =IF(Assessment!$G18="Critical",ROW(Assessment!$G18),"") | Z18: =IF(Assessment!$G18="High",ROW(Assessment!$G18),"")
A19: =IF($X19="","",3) -> 3 | B19: =IF($X19="","",INDEX(Assessment!$A:$A,$X19)) -> TR1-028-a | C19: =IF($X19="","",INDEX(Assessment!$B:$B,$X19)) -> BSI TR-03183-1 v1.0.0 | D19: =IF($X19="","",INDEX(Assessment!$C:$C,$X19)) -> 3.6 Obligations of the manufacturer - PwDE Monitoring and Post-Market Obligations | E19: =IF($X19="","",INDEX(Assessment!$F:$F,$X19)) -> Vulnerability monitoring | F19: =IF($X19="","",INDEX(Assessment!$G:$G,$X19)) -> Critical | G19: =IF($X19="","",INDEX(Assessment!$J:$J,$X19)) -> Operate SBOM-based continuous vulnerability monitoring, periodic security reviews and remediation for all supported releases. | H19: =IF($X19="","",INDEX(Assessment!$L:$L,$X19)) -> PSIRT Lead / Product Security Officer | I19: =IF($X19="","",INDEX(Assessment!$N:$N,$X19)) -> L | X19: =IF(3<=$B$6,SMALL($Y$2:$Y$593,3),IF(3<=$B$6+$B$7,SMALL($Z$2:$Z$593,3-$B$6),"")) -> 33 | Y19: =IF(Assessment!$G19="Critical",ROW(Assessment!$G19),"") | Z19: =IF(Assessment!$G19="High",ROW(Assessment!$G19),"") -> 19
A20: =IF($X20="","",4) -> 4 | B20: =IF($X20="","",INDEX(Assessment!$A:$A,$X20)) -> TR1-028-b | C20: =IF($X20="","",INDEX(Assessment!$B:$B,$X20)) -> BSI TR-03183-1 v1.0.0 | D20: =IF($X20="","",INDEX(Assessment!$C:$C,$X20)) -> 3.6 Obligations of the manufacturer - PwDE Monitoring and Post-Market Obligations | E20: =IF($X20="","",INDEX(Assessment!$F:$F,$X20)) -> Vulnerability remediation | F20: =IF($X20="","",INDEX(Assessment!$G:$G,$X20)) -> Critical | G20: =IF($X20="","",INDEX(Assessment!$J:$J,$X20)) -> Operate SBOM-based continuous vulnerability monitoring, periodic security reviews and remediation for all supported releases. | H20: =IF($X20="","",INDEX(Assessment!$L:$L,$X20)) -> PSIRT Lead / Product Security Officer | I20: =IF($X20="","",INDEX(Assessment!$N:$N,$X20)) -> L | X20: =IF(4<=$B$6,SMALL($Y$2:$Y$593,4),IF(4<=$B$6+$B$7,SMALL($Z$2:$Z$593,4-$B$6),"")) -> 34 | Y20: =IF(Assessment!$G20="Critical",ROW(Assessment!$G20),"") | Z20: =IF(Assessment!$G20="High",ROW(Assessment!$G20),"")
A21: =IF($X21="","",5) -> 5 | B21: =IF($X21="","",INDEX(Assessment!$A:$A,$X21)) -> TR1-032-a | C21: =IF($X21="","",INDEX(Assessment!$B:$B,$X21)) -> BSI TR-03183-1 v1.0.0 | D21: =IF($X21="","",INDEX(Assessment!$C:$C,$X21)) -> 3.6 Obligations of the manufacturer - Reporting obligations | E21: =IF($X21="","",INDEX(Assessment!$F:$F,$X21)) -> CRA Art. 14 reporting - vulnerabilities | F21: =IF($X21="","",INDEX(Assessment!$G:$G,$X21)) -> Critical | G21: =IF($X21="","",INDEX(Assessment!$J:$J,$X21)) -> Implement the reporting procedure: awareness criteria, 24h / 72h / 14-day (vulnerability) and 24h / 72h / one-month (incident) timelines, platform accounts, templates, approvals and 24/7 escalation; rehearse it. | H21: =IF($X21="","",INDEX(Assessment!$L:$L,$X21)) -> PSIRT Lead / Compliance Officer | I21: =IF($X21="","",INDEX(Assessment!$N:$N,$X21)) -> L | X21: =IF(5<=$B$6,SMALL($Y$2:$Y$593,5),IF(5<=$B$6+$B$7,SMALL($Z$2:$Z$593,5-$B$6),"")) -> 40 | Y21: =IF(Assessment!$G21="Critical",ROW(Assessment!$G21),"") | Z21: =IF(Assessment!$G21="High",ROW(Assessment!$G21),"")
A22: =IF($X22="","",6) -> 6 | B22: =IF($X22="","",INDEX(Assessment!$A:$A,$X22)) -> TR1-032-b | C22: =IF($X22="","",INDEX(Assessment!$B:$B,$X22)) -> BSI TR-03183-1 v1.0.0 | D22: =IF($X22="","",INDEX(Assessment!$C:$C,$X22)) -> 3.6 Obligations of the manufacturer - Reporting obligations | E22: =IF($X22="","",INDEX(Assessment!$F:$F,$X22)) -> CRA Art. 14 reporting - incidents | F22: =IF($X22="","",INDEX(Assessment!$G:$G,$X22)) -> Critical | G22: =IF($X22="","",INDEX(Assessment!$J:$J,$X22)) -> Implement the reporting procedure: awareness criteria, 24h / 72h / 14-day (vulnerability) and 24h / 72h / one-month (incident) timelines, platform accounts, templates, approvals and 24/7 escalation; rehearse it. | H22: =IF($X22="","",INDEX(Assessment!$L:$L,$X22)) -> PSIRT Lead / Compliance Officer | I22: =IF($X22="","",INDEX(Assessment!$N:$N,$X22)) -> L | X22: =IF(6<=$B$6,SMALL($Y$2:$Y$593,6),IF(6<=$B$6+$B$7,SMALL($Z$2:$Z$593,6-$B$6),"")) -> 41 | Y22: =IF(Assessment!$G22="Critical",ROW(Assessment!$G22),"") | Z22: =IF(Assessment!$G22="High",ROW(Assessment!$G22),"")
A23: =IF($X23="","",7) -> 7 | B23: =IF($X23="","",INDEX(Assessment!$A:$A,$X23)) -> TR1-033 | C23: =IF($X23="","",INDEX(Assessment!$B:$B,$X23)) -> BSI TR-03183-1 v1.0.0 | D23: =IF($X23="","",INDEX(Assessment!$C:$C,$X23)) -> 3.6 Obligations of the manufacturer - Reporting obligations | E23: =IF($X23="","",INDEX(Assessment!$F:$F,$X23)) -> CRA Art. 14 reporting - channel | F23: =IF($X23="","",INDEX(Assessment!$G:$G,$X23)) -> Critical | G23: =IF($X23="","",INDEX(Assessment!$J:$J,$X23)) -> Implement the reporting procedure: awareness criteria, 24h / 72h / 14-day (vulnerability) and 24h / 72h / one-month (incident) timelines, platform accounts, templates, approvals and 24/7 escalation; rehearse it. | H23: =IF($X23="","",INDEX(Assessment!$L:$L,$X23)) -> PSIRT Lead / Compliance Officer | I23: =IF($X23="","",INDEX(Assessment!$N:$N,$X23)) -> L | X23: =IF(7<=$B$6,SMALL($Y$2:$Y$593,7),IF(7<=$B$6+$B$7,SMALL($Z$2:$Z$593,7-$B$6),"")) -> 42 | Y23: =IF(Assessment!$G23="Critical",ROW(Assessment!$G23),"") | Z23: =IF(Assessment!$G23="High",ROW(Assessment!$G23),"")
A24: =IF($X24="","",8) -> 8 | B24: =IF($X24="","",INDEX(Assessment!$A:$A,$X24)) -> TR1-034-a | C24: =IF($X24="","",INDEX(Assessment!$B:$B,$X24)) -> BSI TR-03183-1 v1.0.0 | D24: =IF($X24="","",INDEX(Assessment!$C:$C,$X24)) -> 3.6 Obligations of the manufacturer - Reporting obligations | E24: =IF($X24="","",INDEX(Assessment!$F:$F,$X24)) -> CRA Art. 14 reporting - vulnerabilities | F24: =IF($X24="","",INDEX(Assessment!$G:$G,$X24)) -> Critical | G24: =IF($X24="","",INDEX(Assessment!$J:$J,$X24)) -> Implement the reporting procedure: awareness criteria, 24h / 72h / 14-day (vulnerability) and 24h / 72h / one-month (incident) timelines, platform accounts, templates, approvals and 24/7 escalation; rehearse it. | H24: =IF($X24="","",INDEX(Assessment!$L:$L,$X24)) -> PSIRT Lead / Compliance Officer | I24: =IF($X24="","",INDEX(Assessment!$N:$N,$X24)) -> L | X24: =IF(8<=$B$6,SMALL($Y$2:$Y$593,8),IF(8<=$B$6+$B$7,SMALL($Z$2:$Z$593,8-$B$6),"")) -> 43 | Y24: =IF(Assessment!$G24="Critical",ROW(Assessment!$G24),"") | Z24: =IF(Assessment!$G24="High",ROW(Assessment!$G24),"")
A25: =IF($X25="","",9) -> 9 | B25: =IF($X25="","",INDEX(Assessment!$A:$A,$X25)) -> TR1-035 | C25: =IF($X25="","",INDEX(Assessment!$B:$B,$X25)) -> BSI TR-03183-1 v1.0.0 | D25: =IF($X25="","",INDEX(Assessment!$C:$C,$X25)) -> 3.6 Obligations of the manufacturer - Reporting obligations | E25: =IF($X25="","",INDEX(Assessment!$F:$F,$X25)) -> CRA Art. 14 reporting - vulnerabilities | F25: =IF($X25="","",INDEX(Assessment!$G:$G,$X25)) -> Critical | G25: =IF($X25="","",INDEX(Assessment!$J:$J,$X25)) -> Implement the reporting procedure: awareness criteria, 24h / 72h / 14-day (vulnerability) and 24h / 72h / one-month (incident) timelines, platform accounts, templates, approvals and 24/7 escalation; rehearse it. | H25: =IF($X25="","",INDEX(Assessment!$L:$L,$X25)) -> PSIRT Lead / Compliance Officer | I25: =IF($X25="","",INDEX(Assessment!$N:$N,$X25)) -> L | X25: =IF(9<=$B$6,SMALL($Y$2:$Y$593,9),IF(9<=$B$6+$B$7,SMALL($Z$2:$Z$593,9-$B$6),"")) -> 45 | Y25: =IF(Assessment!$G25="Critical",ROW(Assessment!$G25),"") | Z25: =IF(Assessment!$G25="High",ROW(Assessment!$G25),"")
A26: =IF($X26="","",10) -> 10 | B26: =IF($X26="","",INDEX(Assessment!$A:$A,$X26)) -> TR1-038 | C26: =IF($X26="","",INDEX(Assessment!$B:$B,$X26)) -> BSI TR-03183-1 v1.0.0 | D26: =IF($X26="","",INDEX(Assessment!$C:$C,$X26)) -> 3.6 Obligations of the manufacturer - Reporting obligations | E26: =IF($X26="","",INDEX(Assessment!$F:$F,$X26)) -> CRA Art. 14 reporting - vulnerabilities | F26: =IF($X26="","",INDEX(Assessment!$G:$G,$X26)) -> Critical | G26: =IF($X26="","",INDEX(Assessment!$J:$J,$X26)) -> Implement the reporting procedure: awareness criteria, 24h / 72h / 14-day (vulnerability) and 24h / 72h / one-month (incident) timelines, platform accounts, templates, approvals and 24/7 escalation; rehearse it. | H26: =IF($X26="","",INDEX(Assessment!$L:$L,$X26)) -> PSIRT Lead / Compliance Officer | I26: =IF($X26="","",INDEX(Assessment!$N:$N,$X26)) -> L | X26: =IF(10<=$B$6,SMALL($Y$2:$Y$593,10),IF(10<=$B$6+$B$7,SMALL($Z$2:$Z$593,10-$B$6),"")) -> 48 | Y26: =IF(Assessment!$G26="Critical",ROW(Assessment!$G26),"") | Z26: =IF(Assessment!$G26="High",ROW(Assessment!$G26),"")
A27: =IF($X27="","",11) -> 11 | B27: =IF($X27="","",INDEX(Assessment!$A:$A,$X27)) -> TR1-040 | C27: =IF($X27="","",INDEX(Assessment!$B:$B,$X27)) -> BSI TR-03183-1 v1.0.0 | D27: =IF($X27="","",INDEX(Assessment!$C:$C,$X27)) -> 3.6 Obligations of the manufacturer - Reporting obligations | E27: =IF($X27="","",INDEX(Assessment!$F:$F,$X27)) -> CRA Art. 14 reporting - incidents | F27: =IF($X27="","",INDEX(Assessment!$G:$G,$X27)) -> Critical | G27: =IF($X27="","",INDEX(Assessment!$J:$J,$X27)) -> Implement the reporting procedure: awareness criteria, 24h / 72h / 14-day (vulnerability) and 24h / 72h / one-month (incident) timelines, platform accounts, templates, approvals and 24/7 escalation; rehearse it. | H27: =IF($X27="","",INDEX(Assessment!$L:$L,$X27)) -> PSIRT Lead / Compliance Officer | I27: =IF($X27="","",INDEX(Assessment!$N:$N,$X27)) -> L | X27: =IF(11<=$B$6,SMALL($Y$2:$Y$593,11),IF(11<=$B$6+$B$7,SMALL($Z$2:$Z$593,11-$B$6),"")) -> 50 | Y27: =IF(Assessment!$G27="Critical",ROW(Assessment!$G27),"") | Z27: =IF(Assessment!$G27="High",ROW(Assessment!$G27),"")
A28: =IF($X28="","",12) -> 12 | B28: =IF($X28="","",INDEX(Assessment!$A:$A,$X28)) -> TR1-042 | C28: =IF($X28="","",INDEX(Assessment!$B:$B,$X28)) -> BSI TR-03183-1 v1.0.0 | D28: =IF($X28="","",INDEX(Assessment!$C:$C,$X28)) -> 3.6 Obligations of the manufacturer - Reporting obligations | E28: =IF($X28="","",INDEX(Assessment!$F:$F,$X28)) -> CRA Art. 14 reporting - incidents | F28: =IF($X28="","",INDEX(Assessment!$G:$G,$X28)) -> Critical | G28: =IF($X28="","",INDEX(Assessment!$J:$J,$X28)) -> Implement the reporting procedure: awareness criteria, 24h / 72h / 14-day (vulnerability) and 24h / 72h / one-month (incident) timelines, platform accounts, templates, approvals and 24/7 escalation; rehearse it. | H28: =IF($X28="","",INDEX(Assessment!$L:$L,$X28)) -> PSIRT Lead / Compliance Officer | I28: =IF($X28="","",INDEX(Assessment!$N:$N,$X28)) -> L | X28: =IF(12<=$B$6,SMALL($Y$2:$Y$593,12),IF(12<=$B$6+$B$7,SMALL($Z$2:$Z$593,12-$B$6),"")) -> 53 | Y28: =IF(Assessment!$G28="Critical",ROW(Assessment!$G28),"") | Z28: =IF(Assessment!$G28="High",ROW(Assessment!$G28),"")
A29: =IF($X29="","",13) -> 13 | B29: =IF($X29="","",INDEX(Assessment!$A:$A,$X29)) -> TR1-045 | C29: =IF($X29="","",INDEX(Assessment!$B:$B,$X29)) -> BSI TR-03183-1 v1.0.0 | D29: =IF($X29="","",INDEX(Assessment!$C:$C,$X29)) -> 3.6 Obligations of the manufacturer - Reporting obligations | E29: =IF($X29="","",INDEX(Assessment!$F:$F,$X29)) -> CRA Art. 14 reporting - incidents | F29: =IF($X29="","",INDEX(Assessment!$G:$G,$X29)) -> Critical | G29: =IF($X29="","",INDEX(Assessment!$J:$J,$X29)) -> Implement the reporting procedure: awareness criteria, 24h / 72h / 14-day (vulnerability) and 24h / 72h / one-month (incident) timelines, platform accounts, templates, approvals and 24/7 escalation; rehearse it. | H29: =IF($X29="","",INDEX(Assessment!$L:$L,$X29)) -> PSIRT Lead / Compliance Officer | I29: =IF($X29="","",INDEX(Assessment!$N:$N,$X29)) -> L | X29: =IF(13<=$B$6,SMALL($Y$2:$Y$593,13),IF(13<=$B$6+$B$7,SMALL($Z$2:$Z$593,13-$B$6),"")) -> 56 | Y29: =IF(Assessment!$G29="Critical",ROW(Assessment!$G29),"") | Z29: =IF(Assessment!$G29="High",ROW(Assessment!$G29),"")
A30: =IF($X30="","",14) -> 14 | B30: =IF($X30="","",INDEX(Assessment!$A:$A,$X30)) -> VH.1 | C30: =IF($X30="","",INDEX(Assessment!$B:$B,$X30)) -> BSI TR-03183-1 v1.0.0 | D30: =IF($X30="","",INDEX(Assessment!$C:$C,$X30)) -> Annex B Table 10 (CRA Annex I Part II (1)); text also in 3.9 | E30: =IF($X30="","",INDEX(Assessment!$F:$F,$X30)) -> Vulnerability handling - identification | F30: =IF($X30="","",INDEX(Assessment!$G:$G,$X30)) -> Critical | G30: =IF($X30="","",INDEX(Assessment!$J:$J,$X30)) -> Implement, document and operate: identify and document vulnerabilities and components contained in products. | H30: =IF($X30="","",INDEX(Assessment!$L:$L,$X30)) -> PSIRT Lead | I30: =IF($X30="","",INDEX(Assessment!$N:$N,$X30)) -> L | X30: =IF(14<=$B$6,SMALL($Y$2:$Y$593,14),IF(14<=$B$6+$B$7,SMALL($Z$2:$Z$593,14-$B$6),"")) -> 257 | Y30: =IF(Assessment!$G30="Critical",ROW(Assessment!$G30),"") | Z30: =IF(Assessment!$G30="High",ROW(Assessment!$G30),"")
A31: =IF($X31="","",15) -> 15 | B31: =IF($X31="","",INDEX(Assessment!$A:$A,$X31)) -> VH.2a-a | C31: =IF($X31="","",INDEX(Assessment!$B:$B,$X31)) -> BSI TR-03183-1 v1.0.0 | D31: =IF($X31="","",INDEX(Assessment!$C:$C,$X31)) -> Annex B Table 10 (CRA Annex I Part II (2)); text also in 3.9 | E31: =IF($X31="","",INDEX(Assessment!$F:$F,$X31)) -> Vulnerability handling - remediation | F31: =IF($X31="","",INDEX(Assessment!$G:$G,$X31)) -> Critical | G31: =IF($X31="","",INDEX(Assessment!$J:$J,$X31)) -> Implement, document and operate: address and remediate vulnerabilities without delay, incl. security updates. | H31: =IF($X31="","",INDEX(Assessment!$L:$L,$X31)) -> PSIRT Lead | I31: =IF($X31="","",INDEX(Assessment!$N:$N,$X31)) -> L | X31: =IF(15<=$B$6,SMALL($Y$2:$Y$593,15),IF(15<=$B$6+$B$7,SMALL($Z$2:$Z$593,15-$B$6),"")) -> 259 | Y31: =IF(Assessment!$G31="Critical",ROW(Assessment!$G31),"") | Z31: =IF(Assessment!$G31="High",ROW(Assessment!$G31),"") -> 31
A32: =IF($X32="","",16) -> 16 | B32: =IF($X32="","",INDEX(Assessment!$A:$A,$X32)) -> VH.4-a | C32: =IF($X32="","",INDEX(Assessment!$B:$B,$X32)) -> BSI TR-03183-1 v1.0.0 | D32: =IF($X32="","",INDEX(Assessment!$C:$C,$X32)) -> Annex B Table 10 (CRA Annex I Part II (4)); text also in 3.9 | E32: =IF($X32="","",INDEX(Assessment!$F:$F,$X32)) -> Vulnerability disclosure | F32: =IF($X32="","",INDEX(Assessment!$G:$G,$X32)) -> Critical | G32: =IF($X32="","",INDEX(Assessment!$J:$J,$X32)) -> Implement, document and operate: once a security update is available, publicly disclose information about fixed vulnerabilities. | H32: =IF($X32="","",INDEX(Assessment!$L:$L,$X32)) -> PSIRT Lead | I32: =IF($X32="","",INDEX(Assessment!$N:$N,$X32)) -> L | X32: =IF(16<=$B$6,SMALL($Y$2:$Y$593,16),IF(16<=$B$6+$B$7,SMALL($Z$2:$Z$593,16-$B$6),"")) -> 262 | Y32: =IF(Assessment!$G32="Critical",ROW(Assessment!$G32),"") | Z32: =IF(Assessment!$G32="High",ROW(Assessment!$G32),"") -> 32
