Workbook

Sheet Executive Dashboard
A1: EU CYBER RESILIENCE ACT (REGULATION (EU) 2024/2847) — EXECUTIVE COMPLIANCE DASHBOARD
A2: Executive Overview, KPI Scorecards, Toolchain Coverage Metrics & Strategic Roadmap | Baseline: Standard Commercial Product with Digital Elements | October 2026
A4: TOTAL CRA OBLIGATIONS | C4: MANDATORY OBLIGATIONS | D4: CONDITIONAL CLAUSES | E4: ARTICLE 14 REPORTING DUTY | G4: CRITICAL REMEDIATION GAPS | I4: RESIDUAL GOVERNANCE GAPS
A5: =COUNTA('CRA Requirements Matrix'!A4:A46) | C5: =COUNTIF('CRA Requirements Matrix'!F4:F46, "*Mandatory*") | D5: =COUNTIF('CRA Requirements Matrix'!F4:F46, "*Conditional*") | E5: LIVE (11 Sept 2026) | G5: =COUNTIF('CRA Requirements Matrix'!AC4:AC46, "Critical*") | I5: =COUNTA('Compliance Gaps & Roadmap'!A4:A23)
A6: Independently assessable legal requirements | C6: Strict baseline statutory requirements | D6: Tailored B2B / context-specific clauses | E6: MANDATORY & ENFORCEABLE RIGHT NOW | G6: Immediate compliance priority items | I6: Gaps requiring non-tool policies / legal SOPs
A8: 1. EXECUTIVE REGULATORY CONTEXT & STRATEGIC MANDATE
A9: On 20 November 2024, the European Union published Regulation (EU) 2024/2847 (Cyber Resilience Act — CRA; OJ L, 2024/2847), establishing a mandatory horizontal regulatory framework for products with digital elements (PDEs) placed on the EU single market. Unlike voluntary security certifications (ISO 27001, SOC 2), the CRA enforces direct product-level essential requirements (Annex I), continuous vulnerability handling, and statutory administrative fines of up to €15,000,000 or 2.5% of global turnover. CRITICAL ENFORCEMENT TIMELINE DISTINCTION (AS OF OCTOBER 2026): • LIVE TODAY (Statutory Duty since 11 September 2026): Article 14 incident and actively exploited vulnerability reporting is fully live and enforceable right now via the ENISA Single Reporting Platform (SRP). It applies retroactively to all products currently in use on the EU market. • TARGET DATE (11 December 2027): General application of Annex I essential requirements, conformity assessment (Module A/B/C/H), CE marking, and technical documentation (Annex VII) becomes mandatory for all market placements. CORE ARCHITECTURAL FINDING: Automated security tools (SAST, SCA, DAST, Container Scanning) provide vital technical detection and evidence generation for ~28% of CRA requirements. However, more than 50% of CRA obligations represent non-tool organizational, legal, and operational duties—including statutory CSIRT reporting, Coordinated Vulnerability Disclosure (CVD), minimum 5-year support periods, 10-year update archives, Annex VII dossiers, and EU Declarations of Conformity.
A15: 2. SECURITY TOOLCHAIN COVERAGE SCORECARD (DYNAMIC SYNCHRONIZATION WITH SHEET 2)
A16: Security Tool / Activity | B16: Tool Category | C16: Total Reqs | D16: Full Coverage | E16: Full % | F16: Partial Coverage | G16: Partial % | H16: Direct Tech Contribution % | I16: None % (Gaps) | J16: Primary Lifecycle Phase Focus
A17: ='Tool Coverage Summary'!A21 | B17: ='Tool Coverage Summary'!B21 | C17: ='Tool Coverage Summary'!B21 | D17: ='Tool Coverage Summary'!C21 | E17: ='Tool Coverage Summary'!D21 | F17: ='Tool Coverage Summary'!E21 | G17: ='Tool Coverage Summary'!F21 | H17: ='Tool Coverage Summary'!I21 | I17: ='Tool Coverage Summary'!H21 | J17: ='Tool Coverage Summary'!J21
A18: ='Tool Coverage Summary'!A22 | B18: ='Tool Coverage Summary'!B22 | C18: ='Tool Coverage Summary'!B22 | D18: ='Tool Coverage Summary'!C22 | E18: ='Tool Coverage Summary'!D22 | F18: ='Tool Coverage Summary'!E22 | G18: ='Tool Coverage Summary'!F22 | H18: ='Tool Coverage Summary'!I22 | I18: ='Tool Coverage Summary'!H22 | J18: ='Tool Coverage Summary'!J22
A19: ='Tool Coverage Summary'!A23 | B19: ='Tool Coverage Summary'!B23 | C19: ='Tool Coverage Summary'!B23 | D19: ='Tool Coverage Summary'!C23 | E19: ='Tool Coverage Summary'!D23 | F19: ='Tool Coverage Summary'!E23 | G19: ='Tool Coverage Summary'!F23 | H19: ='Tool Coverage Summary'!I23 | I19: ='Tool Coverage Summary'!H23 | J19: ='Tool Coverage Summary'!J23
A20: ='Tool Coverage Summary'!A24 | B20: ='Tool Coverage Summary'!B24 | C20: ='Tool Coverage Summary'!B24 | D20: ='Tool Coverage Summary'!C24 | E20: ='Tool Coverage Summary'!D24 | F20: ='Tool Coverage Summary'!E24 | G20: ='Tool Coverage Summary'!F24 | H20: ='Tool Coverage Summary'!I24 | I20: ='Tool Coverage Summary'!H24 | J20: ='Tool Coverage Summary'!J24
A21: ='Tool Coverage Summary'!A25 | B21: ='Tool Coverage Summary'!B25 | C21: ='Tool Coverage Summary'!B25 | D21: ='Tool Coverage Summary'!C25 | E21: ='Tool Coverage Summary'!D25 | F21: ='Tool Coverage Summary'!E25 | G21: ='Tool Coverage Summary'!F25 | H21: ='Tool Coverage Summary'!I25 | I21: ='Tool Coverage Summary'!H25 | J21: ='Tool Coverage Summary'!J25
A22: ='Tool Coverage Summary'!A26 | B22: ='Tool Coverage Summary'!B26 | C22: ='Tool Coverage Summary'!B26 | D22: ='Tool Coverage Summary'!C26 | E22: ='Tool Coverage Summary'!D26 | F22: ='Tool Coverage Summary'!E26 | G22: ='Tool Coverage Summary'!F26 | H22: ='Tool Coverage Summary'!I26 | I22: ='Tool Coverage Summary'!H26 | J22: ='Tool Coverage Summary'!J26
A23: ='Tool Coverage Summary'!A27 | B23: ='Tool Coverage Summary'!B27 | C23: ='Tool Coverage Summary'!B27 | D23: ='Tool Coverage Summary'!C27 | E23: ='Tool Coverage Summary'!D27 | F23: ='Tool Coverage Summary'!E27 | G23: ='Tool Coverage Summary'!F27 | H23: ='Tool Coverage Summary'!I27 | I23: ='Tool Coverage Summary'!H27 | J23: ='Tool Coverage Summary'!J27
A24: ='Tool Coverage Summary'!A28 | B24: ='Tool Coverage Summary'!B28 | C24: ='Tool Coverage Summary'!B28 | D24: ='Tool Coverage Summary'!C28 | E24: ='Tool Coverage Summary'!D28 | F24: ='Tool Coverage Summary'!E28 | G24: ='Tool Coverage Summary'!F28 | H24: ='Tool Coverage Summary'!I28 | I24: ='Tool Coverage Summary'!H28 | J24: ='Tool Coverage Summary'!J28
A25: ='Tool Coverage Summary'!A29 | B25: ='Tool Coverage Summary'!B29 | C25: ='Tool Coverage Summary'!B29 | D25: ='Tool Coverage Summary'!C29 | E25: ='Tool Coverage Summary'!D29 | F25: ='Tool Coverage Summary'!E29 | G25: ='Tool Coverage Summary'!F29 | H25: ='Tool Coverage Summary'!I29 | I25: ='Tool Coverage Summary'!H29 | J25: ='Tool Coverage Summary'!J29
A26: ='Tool Coverage Summary'!A30 | B26: ='Tool Coverage Summary'!B30 | C26: ='Tool Coverage Summary'!B30 | D26: ='Tool Coverage Summary'!C30 | E26: ='Tool Coverage Summary'!D30 | F26: ='Tool Coverage Summary'!E30 | G26: ='Tool Coverage Summary'!F30 | H26: ='Tool Coverage Summary'!I30 | I26: ='Tool Coverage Summary'!H30 | J26: ='Tool Coverage Summary'!J30
A27: Toolchain Portfolio Average | B27: Multi-Layered | C27: 43 | D27: =AVERAGE(D17:D26) | E27: =AVERAGE(E17:E26) | F27: =AVERAGE(F17:F26) | G27: =AVERAGE(G17:G26) | H27: =AVERAGE(H17:H26) | I27: =AVERAGE(I17:I26) | J27: Integrated SDLC Toolchain
A29: 3. LIFECYCLE PHASE READINESS & CONTROL GATE ROLLUP
A30: Lifecycle Phase | B30: Mandatory Action Count | C30: Key Governance Gates | D30: Primary Supporting Tools / Processes | E30: Mandatory Regulatory Deliverables | F30: Estimated Toolchain Coverage Level | G30: Residual Governance Gap Areas | H30: Lead Responsible Stakeholders | I30: Statutory Deadline Cadence | J30: Audit Risk Level
A31: Presales and Product Planning | B31: 6 Actions | C31: Gate 0 (Scope) & Gate 1 (Claims) | D31: TARA, Scope Questionnaire, OpenSSF | E31: Classification Record, 5-Yr Support Statement | F31: Low (~15% - Analytical / Business) | G31: Product classification, support pricing, marketing gating | H31: Presales Lead, Product VP, Legal | I31: Prior to bid / proposal | J31: High
A32: Development | B32: 12 Actions | C32: Sprint Security Gates & DPIA Approval | D32: Coverity, SonarQube, TARA, DPIA | E32: Threat Model, IAM Matrix, Crypto Spec, DPIA | F32: Medium (~50% - SAST / DAST) | G32: Living risk updates, data minimisation, secure defaults | H32: Lead Architect, DevSecOps Lead | I32: Daily / Sprint cadence | J32: Medium
A33: Build and Release | B33: 8 Actions | C33: Build Gates 1-3 & Release Gates 1-5 | D33: Black Duck, Nexus IQ, Sigstore, Pentest | E33: CycloneDX SBOM, Pentest Report, VEX Record | F33: High (~75% - Automated SCA/SAST) | G33: HSM code signing, release gating, CAB substantial checks | H33: DevSecOps Lead, Release Manager | I33: Per release build | J33: High
A34: Deployment and Delivery | B34: 8 Actions | C34: Compliance Gates 1-2 & Delivery Gate | D34: Annex VII Builder, EU DoC Workflow | E34: Annex VII Dossier, Signed EU DoC, CE Mark | F34: Low (~10% - Pure Legal/Conformity) | G34: Dossier assembly, DoC execution, 10-yr compliance vault | H34: CEO, Compliance Officer, Quality | I34: Prior to first customer ship | J34: Critical
A35: Maintenance and RUN | B35: 10 Actions | C35: Operational Gates & Statutory Clocks | D35: Dependency-Track, Cyberwatch, ENISA SRP | E35: Article 14 CSIRT Reports, CSAF Advisories | F35: Medium (~40% - Continuous CVEs) | G35: 24h/72h ENISA SRP filings, 10-yr patch archive, CVD inbox | H35: CISO, PSIRT Lead, Legal Counsel | I35: Continuous (24h/72h statutory) | J35: Critical
A37: 4. STRATEGIC COMPLIANCE ROADMAP RECOMMENDATIONS FOR CISO & ARCHITECTS
A38: 1. IMMEDIATE ACTION (LIVE STATUTORY DUTY — Q4 2026) | C38: Operationalize Article 14 Reporting Runbook immediately. Ensure corporate ENISA Single Reporting Platform (SRP) accounts are active with Primary/Secondary Assigned Representatives (EU Login / FIDO2). Train PSIRT on the 24h Early Warning, 72h Notification, and 14-day Final Report statutory clocks. Deploy RFC 9116 security.txt on all web properties.
A39: 2. SDLC TOOLCHAIN INTEGRATION & GATING (H1 2027) | C39: Integrate automated SBOM generation (CycloneDX/SPDX) into CI/CD pipelines using Black Duck / Nexus IQ and connect to Dependency-Track for continuous post-market monitoring. Enforce Quality Gates in SonarQube/Coverity breaking builds on unresolved Critical vulnerabilities. Deploy HSM-backed artifact signing (Sigstore/Cosign).
A40: 3. CONFORMITY ASSESSMENT & CE MARKING DOSSIER (H2 2027) | C40: Compile the formal Annex VII Technical Documentation Dossier consolidating threat models (TARA), risk assessments, test reports, and SBOMs. If product is Important Class I/II under IR (EU) 2025/2392, engage accredited Notified Body immediately. Finalize Annex II user security guides, execute signed EU DoC, and affix CE mark prior to 11 Dec 2027.

Sheet CRA Requirements Matrix
A1: EU CYBER RESILIENCE ACT (REGULATION (EU) 2024/2847) — COMPLIANCE REQUIREMENTS MATRIX
A2: Coverage Definitions: Full (Direct principal technical evidence within scope) | Partial (Supporting evidence; requires complementary controls) | None (No material direct contribution) | Baseline: Standard Product with Digital Elements placed on EU Market
A3: Requirement ID | B3: CRA Legal Reference | C3: Requirement Title | D3: Requirement Description & Legal Intent | E3: Requirement Type | F3: Applicability | G3: Responsible Stakeholder | H3: Presales / Planning | I3: Development | J3: Build / Release | K3: Deployment | L3: Maintenance / RUN | M3: Implementation Guidance | N3: Recommended Technical & Organisational Controls | O3: Required Evidence & Compliance Deliverables | P3: Verification or Acceptance Criteria | Q3: SonarQube Coverage | R3: Nexus IQ CLM Coverage | S3: Penetration Testing Coverage | T3: Nessus / Cyberwatch Coverage | U3: DPIA Coverage | V3: Threat Analysis / Risk Analysis Coverage | W3: Dependency-Track Coverage | X3: Black Duck Coverage | Y3: Coverity Coverage | Z3: OWASP ZAP / Burp Coverage | AA3: Coverage Limitations & Assumptions | AB3: Additional Controls or Activities Required | AC3: Remediation Priority | AD3: Official Source URL | AE3: Notes & Product-Specific Applicability Considerations
A4: CRA-REQ-GEN-01 | B4: Annex I, Part I, point (1); Art 13(1), Art 13(2) | C4: Secure-by-Design & Risk-Based Engineering Lifecycle | D4: Products with digital elements shall be designed, developed, and produced in such a way that they ensure an appropriate level of cybersecurity based on the risks identified in the manufacturer's cybersecurity risk assessment. | E4: Product cybersecurity | F4: Mandatory (Applies to all products with digital elements without exception) | G4: Lead Security Architect, Systems Engineer, CISO | H4: Yes | I4: Yes | J4: Supporting | K4: Supporting | L4: Supporting | M4: Incorporate threat modelling, secure architecture reviews, and risk assessment into early concept and architecture phases. Security requirements must directly derive from identified threat scenarios (STRIDE/PASTA/IEC 62443). Risk assessment must be updated iteratively as architecture evolves. | N4: Organizational Secure SDLC policy; mandatory threat modeling gates at design review; architectural risk register; security architecture review board sign-off prior to code development. | O4: Formal Threat Model Document; Cybersecurity Risk Assessment Report (Annex VII Dossier); System Architecture Security Specification; Architectural Gate Review Sign-off. | P4: All identified threat vectors have mapped, documented security mitigations; residual cybersecurity risk is formally signed off by Lead Architect and CISO as acceptable. | Q4: None | R4: None | S4: Partial | T4: None | U4: Partial | V4: Full | W4: None | X4: None | Y4: None | Z4: None | AA4: Automated code scanners and vulnerability tools cannot evaluate high-level architecture, threat models, or design intent. Threat Analysis and Risk Analysis (TARA) provides the primary analytical framework. | AB4: Formal Threat Modeling process (STRIDE/PASTA); Secure Architecture Review Board; Risk Assessment Methodology aligned with ISO/IEC 27005 / IEC 62443-4-1. | AC4: Critical | AD4: https://eur-lex.europa.eu/eli/reg/2024/2847/oj | AE4: Foundational requirement underpinning all other Annex I controls. Must be documented in the Annex VII Technical Documentation Dossier.
A5: CRA-REQ-TECH-01 | B5: Annex I, Part I, point (2)(a); Art 3(41) | C5: Absence of Known Exploitable Vulnerabilities at Placement | D5: Products with digital elements shall be delivered without any known exploitable vulnerabilities at the time of placing on the market. | E5: Product cybersecurity | F5: Mandatory (Strict liability condition at the moment of market placement) | G5: DevSecOps Lead, Lead Security Architect, Release Manager | H5: Supporting | I5: Yes | J5: Yes | K5: Yes | L5: Supporting | M5: Implement automated CI/CD gating breaking builds on Critical/High vulnerabilities in custom code or third-party dependencies. Where a known CVE cannot be patched prior to release, conduct a formal VEX (Vulnerability Exploitability eXchange) analysis proving non-exploitability in product context. | N5: Automated SAST/SCA build quality gates; pre-release penetration testing; automated container/OS scanning; formal VEX assessment process (CSAF/CycloneDX VEX) for justified false positives/unexploitable CVEs. | O5: Pre-release SAST scan reports; SCA dependency scan reports; Penetration test final report; Signed VEX Declaration; Release Gate Approval Record. | P5: Zero unresolved Critical/High vulnerabilities without documented, validated 'none_affected' / 'not_exploitable' VEX status; clean penetration testing validation. | Q5: Partial | R5: Partial | S5: Full | T5: Partial | U5: None | V5: Partial | W5: Partial | X5: Partial | Y5: Partial | Z5: Partial | AA5: Scanners detect potential vulnerabilities based on signatures/rules; only manual Penetration Testing and contextual VEX analysis can verify real-world exploitability in the integrated environment. | AB5: Contextual VEX triage board; formal release gating policy; vulnerability waiver process signed by Product Security Officer. | AC5: Critical | AD5: https://eur-lex.europa.eu/eli/reg/2024/2847/oj | AE5: Under Art 3(41), 'exploit' means the capability to breach cybersecurity. Even if upstream CVE exists, if execution path is unreachable, VEX must substantiate this for compliance audit.
A6: CRA-REQ-TECH-02 | B6: Annex I, Part I, point (2)(b) | C6: Secure Default Configuration & Factory Reset Capability | D6: Products with digital elements shall be delivered with a secure default configuration, including the possibility to reset the product to its original state, and ensuring that users are protected against insecure configurations. | E6: Product cybersecurity | F6: Mandatory (Default); Conditional (May be tailored for custom enterprise B2B solutions upon explicit contractual agreement under Recital 64) | G6: System Architect, Product Engineering Lead, Technical Writer | H6: Supporting | I6: Yes | J6: Yes | K6: Yes | L6: Supporting | M6: Enforce secure-by-default parameters: disable insecure legacy protocols (Telnet, HTTP, SMBv1), enforce unique random passwords per device (no default admin/admin), require password changes on first boot, and provide a verified factory reset mechanism that wipes user data while restoring secure baselines. | N6: CIS Benchmark / DISA STIG hardening scripts; automated configuration compliance auditing; cryptographically secured factory reset utility; forced password change on first setup. | O6: CIS Benchmark Configuration Compliance Audit Report; Hardening Specification Document; Factory Reset Verification Test Record; User Manual Secure Configuration Guide (Annex II). | P6: Default installation passes CIS benchmark with zero high-risk deviations; unique per-device credentials verified; factory reset reliably restores hardened baseline and scrubs credentials. | Q6: None | R6: None | S6: Partial | T6: Full | U6: None | V6: Partial | W6: None | X6: None | Y6: None | Z6: Partial | AA6: Code-level SAST and SCA cannot assess deployed system configurations, daemon settings, or reset mechanics. Nessus/Cyberwatch directly audits OS/service hardening against CIS benchmarks. | AB6: Automated OS/firmware hardening automation (Ansible/Puppet); physical/logical reset button testing; user installation guide gating. | AC6: High | AD6: https://eur-lex.europa.eu/eli/reg/2024/2847/oj | AE6: Recital 64 allows tailor-made bespoke B2B software to negotiate specific configuration defaults with customers, provided the waiver is formally documented in the contract.
A7: CRA-REQ-TECH-03 | B7: Annex I, Part I, point (2)(c); Annex I, Part II, point (7) | C7: Automatic Security Updates by Default with User Notification | D7: Products with digital elements shall ensure that security updates are delivered automatically by default where technically feasible, with clear user notifications and opt-out capabilities. | E7: Product cybersecurity | F7: Mandatory (Where technically feasible; conditional exemption for OT/industrial safety systems where unexpected restarts create operational hazards) | G7: Firmware / Platform Architect, Release Engineering Lead, Product Manager | H7: Supporting | I7: Yes | J7: Yes | K7: Yes | L7: Yes | M7: Implement an automated background update mechanism for security patches. Users must receive clear notifications prior to/after installation, have an easy opt-out toggle in UI/CLI, and have the ability to defer reboots. Security patches must be separated from functional updates. | N7: OTA / background update daemon with dual-partition A/B rollback protection; cryptographic signature verification of update packages; update scheduling and user notification UI; opt-out preference persistence. | O7: Update Architecture Specification; Automated Update Mechanism Test Report; Rollback & Anti-Downgrade Test Record; Annex II User Instructions on Update Configuration. | P7: Automated update installs successfully in test environments; invalid/corrupt updates automatically trigger rollback; opt-out setting successfully defers automated deployment. | Q7: None | R7: None | S7: Partial | T7: None | U7: None | V7: Partial | W7: None | X7: None | Y7: None | Z7: None | AA7: Security scanning tools do not build or test update delivery mechanics. Penetration testing can evaluate rollback resistance and signature verification bypasses. | AB7: OTA update infrastructure; code-signing HSM integration; update daemon resilience testing; customer operational release runbook. | AC7: High | AD7: https://eur-lex.europa.eu/eli/reg/2024/2847/oj | AE7: For critical infrastructure or OT devices where automatic updates violate safety standards (e.g. IEC 61508), manufacturers must provide clear justification in Annex VII technical documentation.
A8: CRA-REQ-TECH-04 | B8: Annex I, Part I, point (2)(d) | C8: Protection Against Unauthorized Access & Identity Management | D8: Products with digital elements shall ensure protection from unauthorised access by appropriate control mechanisms, including authentication, identity or access management systems, and report on possible unauthorised access. | E8: Product cybersecurity | F8: Mandatory (Applies to all products with user, administrative, or machine-to-machine interfaces) | G8: Lead Software Architect, DevSecOps Lead, IAM Specialist | H8: Supporting | I8: Yes | J8: Supporting | K8: Yes | L8: Supporting | M8: Implement robust authentication (MFA for administrative interfaces, API key/mTLS for machine interfaces), fine-grained role-based access control (RBAC/ABAC), secure session management (short-lived tokens, secure cookies), rate limiting on authentication endpoints, and brute-force lockout mechanisms. | N8: Centralized IAM framework (OAuth 2.0 / OIDC / SAML); PBKDF2/Argon2/bcrypt password hashing; mTLS for internal service meshes; account lockout policies; RBAC enforcement on all API routes. | O8: IAM Architecture Design Document; RBAC Matrix; Authentication Unit & Integration Test Suites; Penetration Testing Report (Auth/Privilege Escalation); DAST Scan Report. | P8: Zero unauthorized access bypasses in penetration tests; MFA enforced on administrative paths; session tokens cryptographically random with secure flags; brute-force attacks mitigated. | Q8: Partial | R8: None | S8: Full | T8: Partial | U8: Partial | V8: Partial | W8: None | X8: None | Y8: Partial | Z8: Full | AA8: SonarQube/Coverity can detect hardcoded credentials and basic session flaws in code. DAST (OWASP ZAP/Burp) and Penetration Testing provide primary direct validation of runtime authentication/authorization logic. | AB8: Automated API fuzzing for IDOR/BOLA (Broken Object Level Authorization); credential stuffing defenses; periodic identity posture audits. | AC8: Critical | AD8: https://eur-lex.europa.eu/eli/reg/2024/2847/oj | AE8: Covers both human user accounts and automated API / service accounts connecting to or within the PDE and associated Remote Data Processing Solutions (RDPS).
A9: CRA-REQ-TECH-05 | B9: Annex I, Part I, point (2)(e) | C9: Data Confidentiality Protection via State-of-the-Art Cryptography | D9: Products with digital elements shall protect the confidentiality of stored, transmitted or otherwise processed data, personal or other, such as by encrypting relevant data at rest or in transit by state of the art mechanisms. | E9: Product cybersecurity | F9: Mandatory (Applies to all sensitive, credential, telemetry, and personal data processed by the product) | G9: Security Architect, Cryptographic Engineer, Backend Developer | H9: Supporting | I9: Yes | J9: Supporting | K9: Yes | L9: Supporting | M9: Enforce TLS 1.3 (or strictly configured TLS 1.2 with PFS ciphers) for all data in transit. Enforce AES-256-GCM, ChaCha20-Poly1305, or equivalent modern authenticated encryption for data at rest. Securely manage cryptographic keys using KMS/HSM/TPM; never hardcode keys in source code. | N9: Standard cryptographic libraries (OpenSSL FIPS, BouncyCastle, libsodium); automated secret scanning in Git/CI; TLS enforcement proxies; transparent database encryption (TDE) or volume encryption. | O9: Cryptographic Architecture & Key Management Plan; TLS Configuration Audit Report (SSLLabs / Nessus); SAST Secret & Crypto Scan Reports; Static Analysis Crypto API Audit. | P9: No deprecated ciphers (RC4, 3DES, MD5, SHA1, ECB mode) present; zero plaintext transmissions; keys stored outside codebase in HSM/secret vault; automated scans confirm strong crypto. | Q9: Partial | R9: None | S9: Partial | T9: Partial | U9: Partial | V9: Partial | W9: None | X9: None | Y9: Partial | Z9: Partial | AA9: SonarQube and Coverity detect weak crypto algorithms and hardcoded secrets in code; Nessus verifies TLS cipher suites in runtime. Cryptographic key lifecycle management requires architectural policies. | AB9: Key Management System (KMS) governance; automated Secret Scanner (TruffleHog/GitGuardian); Cryptographic Bill of Materials (CBOM) tracking. | AC9: High | AD9: https://eur-lex.europa.eu/eli/reg/2024/2847/oj | AE9: Alignment with ENISA guidance on cryptographic algorithms and key sizes is strongly recommended to substantiate 'state of the art' legal threshold.
A10: CRA-REQ-TECH-06 | B10: Annex I, Part I, point (2)(f) | C10: Data & Execution Integrity Protection | D10: Products with digital elements shall protect the integrity of stored, transmitted or otherwise processed data, personal or other, commands, programs and configuration against manipulation or tampering. | E10: Product cybersecurity | F10: Mandatory (All critical data streams, firmware images, system files, and command channels) | G10: Lead Software Architect, DevSecOps Lead, Systems Engineer | H10: Supporting | I10: Yes | J10: Yes | K10: Yes | L10: Supporting | M10: Implement cryptographic signatures (ECDSA/RSA) for firmware, configuration files, and software updates. Use secure boot mechanisms (UEFI Secure Boot, hardware root of trust). Protect API requests against tampering using HMAC, digital signatures, or TLS integrity. Implement memory safety controls against memory corruption tampering. | N10: Code signing in CI/CD pipeline using hardware HSM; Secure Boot verification; File Integrity Monitoring (FIM); HMAC message authentication; parameterized queries and input validation preventing memory/state corruption. | O10: Secure Boot & Code Signing Verification Spec; CI/CD Artifact Signing Logs; File Integrity Monitoring Baseline; Pentest Tampering Assessment Report. | P10: System rejects unsigned/tampered binaries and updates; memory corruption attacks cannot overwrite execution flow; API rejects tampered parameters; FIM alerts on unauthorized configuration changes. | Q10: Partial | R10: None | S10: Partial | T10: None | U10: Partial | V10: Partial | W10: None | X10: None | Y10: Partial | Z10: Partial | AA10: SAST (Coverity/SonarQube) detects unsafe memory manipulation and deserialization in code. Penetration testing tests data tampering and command injection in transit. HSM code-signing requires infrastructure controls. | AB10: Enterprise Code Signing Infrastructure; Sigstore / Cosign container signing; Hardware Security Module (HSM) key protection; SLSA build level verification. | AC10: High | AD10: https://eur-lex.europa.eu/eli/reg/2024/2847/oj | AE10: Covers both data at rest/transit and the execution runtime environment to prevent malicious code injection and binary modification.
A11: CRA-REQ-TECH-07 | B11: Annex I, Part I, point (2)(g) | C11: Data Minimisation & Processing Proportionality | D11: Products with digital elements shall process only data, personal or other, that are adequate, relevant and limited to what is necessary in relation to the intended purpose of the product. | E11: Product cybersecurity | F11: Mandatory (Applies to all data collection, telemetry, analytics, and operational logging) | G11: Data Protection Officer (DPO), Product Manager, Lead Architect | H11: Yes | I11: Yes | J11: Supporting | K11: Supporting | L11: Supporting | M11: Apply privacy-by-design and data minimisation principles across all features. Remove unnecessary telemetry collection; anonymize/pseudonymize diagnostic data; provide user controls to disable telemetry; establish automated data retention and pruning schedules. | N11: Data flow mapping; DPIA execution; configurable telemetry opt-out switches; automated database purge jobs; schema reviews preventing excessive field capture. | O11: Data Protection Impact Assessment (DPIA) Report; Data Inventory and Processing Register (GDPR Art 30 / CRA); Telemetry Configuration Architecture; Privacy Policy / Annex II Disclosure. | P11: DPIA approved by DPO; no unneeded personal or sensitive data ingested; telemetry collection strictly opt-in or easily disabled; automated data purging verified. | Q11: None | R11: None | S11: None | T11: None | U11: Full | V11: Partial | W11: None | X11: None | Y11: None | Z11: None | AA11: Technical vulnerability scanners have zero capability to assess legal data minimization or processing necessity. The DPIA process directly and specifically addresses this legal requirement. | AB11: Formal GDPR Art 35 DPIA process; Product Privacy Review Gate; Telemetry opt-out UX validation. | AC11: Medium | AD11: https://eur-lex.europa.eu/eli/reg/2024/2847/oj | AE11: Extends beyond GDPR personal data to cover any non-personal data where excessive collection increases cyberattack blast radius.
A12: CRA-REQ-TECH-08 | B12: Annex I, Part I, point (2)(h) | C12: Essential Function Availability & Denial-of-Service Resilience | D12: Products with digital elements shall protect the availability of essential functions, including resilience against and mitigation of denial-of-service attacks. | E12: Product cybersecurity | F12: Mandatory (Critical for products providing operational or network services) | G12: Infrastructure Architect, Lead Backend Engineer, Network Engineer | H12: Supporting | I12: Yes | J12: Supporting | K12: Yes | L12: Yes | M12: Architect system with graceful degradation and circuit breakers. Implement rate limiting on APIs, resource quotas (CPU, memory, file descriptors, connection limits), request size caps, and anti-amplification controls. For cloud/RDPS backends, deploy DDoS mitigation (CDN, WAF, autoscaling). | N12: API gateway rate limiting (Token Bucket / Leaky Bucket); ingress request throttling; WAF DDoS protection rules; resource cgroups / container quotas; connection timeout configurations; algorithmic ReDoS protections. | O12: High Availability & DoS Resilience Architecture Spec; Stress / Load / DoS Simulation Test Report; Penetration Test DoS Resistance Assessment; Cloud WAF Configuration. | P12: System maintains essential services under sustained simulated traffic spikes/attacks; rate-limiting drops excessive requests without crashing backends; no algorithmic ReDoS crashes. | Q12: Partial | R12: None | S12: Full | T12: Partial | U12: None | V12: Partial | W12: None | X12: None | Y12: Partial | Z12: Partial | AA12: SAST tools detect algorithmic complexity flaws (ReDoS) or resource leaks in code; Nessus identifies known DoS CVEs in services. Penetration testing and automated stress testing provide primary empirical verification. | AB12: Automated Chaos Engineering / DDoS simulation testing; CDN/WAF DDoS mitigation infrastructure; rate-limiting integration tests. | AC12: High | AD12: https://eur-lex.europa.eu/eli/reg/2024/2847/oj | AE12: Essential functions must be explicitly defined in the Annex VII technical documentation and categorized according to failure impact.
A13: CRA-REQ-TECH-09 | B13: Annex I, Part I, point (2)(i) | C13: Minimisation of Impact on External Networks & Connected Devices | D13: Products with digital elements shall minimise the negative impact by the products themselves or connected devices on the availability of services provided by other devices or networks. | E13: Product cybersecurity | F13: Mandatory (Critical for networked devices, IoT endpoints, and client software) | G13: Network Architect, Systems Engineer, Firmware Developer | H13: Supporting | I13: Yes | J13: Supporting | K13: Yes | L13: Supporting | M13: Prevent product from being weaponized as a botnet node, DDoS reflector, or network flood amplifier. Disable open DNS resolvers, NTP amplification, UPnP, and open proxying. Implement egress filtering, outbound connection rate limiting, and exponential backoff on retries. | N13: Outbound connection rate limiting; disabling reflection/amplification protocols; DNS request throttling; strict egress firewall rules; jittered exponential backoff on connection retries. | O13: Network Protocol & Egress Control Specification; Network Traffic Flood / Amplification Test Report; Penetration Test Network Abuse Assessment. | P13: Product cannot be coerced into generating amplified reflection traffic; outbound retry storms throttled during network outages; no open relay or proxy behavior. | Q13: None | R13: None | S13: Partial | T13: Partial | U13: None | V13: Partial | W13: None | X13: None | Y13: None | Z13: Partial | AA13: Nessus scans identify open amplification protocols (DNS, NTP, SNMP, UPnP). Penetration testing and DAST (Burp) test for SSRF and outbound proxy abuse. | AB13: Network abuse prevention testing; egress traffic filtering verification; outbound retry circuit breakers. | AC13: Medium | AD13: https://eur-lex.europa.eu/eli/reg/2024/2847/oj | AE13: Designed to prevent widespread Mirai-style IoT botnet recruitment and cascading infrastructure disruption across the EU digital single market.
A14: CRA-REQ-TECH-10 | B14: Annex I, Part I, point (2)(j) | C14: Attack Surface Reduction & Interface Pruning | D14: Products with digital elements shall be designed, developed and produced to limit attack surfaces, including external interfaces, to what is strictly necessary. | E14: Product cybersecurity | F14: Mandatory (Applies to all software, hardware, and network interfaces) | G14: Lead Security Architect, Systems Engineer, Embedded/Platform Lead | H14: Supporting | I14: Yes | J14: Yes | K14: Yes | L14: Supporting | M14: Identify and eliminate unused network ports, background services, APIs, debug interfaces (JTAG, UART, SSH/telnet debug shells), and unneeded software packages. Apply minimal OS images (Distroless, Alpine, minimal Yocto builds). Expose only documented endpoints required for intended functionality. | N14: Port lockdown and firewalling; removal of debug tools/symbols from production builds; minimal base container images; API gateway endpoint whitelisting; dead code pruning. | O14: Interface & Port Inventory Document; Port Scan Audit Report (Nessus/Nmap); Build Pipeline Hardening Spec (Debug Symbol Stripping); Penetration Test Attack Surface Assessment. | P14: Only explicitly justified ports open in production builds; debug interfaces physically/logically disabled; minimal container attack surface verified by scanner. | Q14: Partial | R14: Partial | S14: Partial | T14: Full | U14: None | V14: Full | W14: None | X14: Partial | Y14: Partial | Z14: Partial | AA14: Threat Modeling (TARA) establishes the architectural attack surface baseline; Nessus directly audits running network ports and services; Black Duck/Nexus identify unused dependency bloat. | AB14: Continuous port scanning in staging/production; container base image slimming; CI build compiler flag enforcement (`-O2 -s`). | AC14: High | AD14: https://eur-lex.europa.eu/eli/reg/2024/2847/oj | AE14: Must document all exposed external interfaces and communication protocols in the Annex VII Technical Documentation Dossier.
... A46: CRA-REQ-SUP-01 | B46: Arts 17–20 | C46: Supply Chain Due Diligence, Importer Verification & Distributor Compliance | D46: Economic operators across the supply chain (importers and distributors) shall verify that the manufacturer has carried out the conformity assessment, drawn up technical documentation, affixed the CE marking, and provided user instructions before making products available. | E46: Governance | F46: Mandatory (Applies to all distribution channels, value-added resellers, importers, and procurement agreements) | G46: Supply Chain Director, Procurement Lead, Partner Operations Manager | H46: Yes | I46: No | J46: Supporting | K46: Yes | L46: Supporting | M46: Establish supply chain verification controls across all distribution channels: verify that hardware/software partners hold valid CE marks, complete Annex VII dossiers, signed EU Declarations of Conformity, and compliant Annex II user instructions. Contractually bind distributors not to alter product security parameters or supply non-compliant units. | N46: Partner Compliance Verification Checklist; distributor contract addenda (CRA compliance clauses); inbound shipment CE mark inspections; distributor training program. | O46: Distributor & Importer Compliance Audit Records; Inbound Product Inspection Logs; Executed Partner Master Services Agreement CRA Addenda; Distributor Verification Registry. | P46: 100% of commercial distribution partners bound by CRA compliance terms; zero third-party products distributed without verified CE mark and EU DoC. | Q46: None | R46: None | S46: None | T46: None | U46: None | V46: None | W46: None | X46: None | Y46: None | Z46: None | AA46: Zero tool coverage. Commercial contract management, supply chain governance, and channel partner oversight. | AB46: CRA Commercial Partner Addendum; channel distribution auditing; inbound quality control inspection SOP. | AC46: High | AD46: https://eur-lex.europa.eu/eli/reg/2024/2847/oj | AE46: If an importer or distributor modifies a product or markets it under their own brand, they legally become the manufacturer under Art 21 or 22.

Sheet Tool Coverage Summary
A1: SECURITY TOOLCHAIN COVERAGE EVALUATION & STATISTICAL GAP ANALYSIS
A2: Assessment of 10 Security Products & Activities against Regulation (EU) 2024/2847 | Denominator: 43 Evaluated CRA Requirements
A4: TABLE A: TOOL CAPABILITIES, OPERATING MODELS & REGULATORY PROFILES
A5: Tool / Activity Name | B5: Operating Model / Category | C5: Primary Security Purpose | D5: Relevant CRA Requirements Supported | E5: Lifecycle Phases Supported | F5: Direct Capabilities & Technical Strengths | G5: Coverage Limitations & Regulatory Blind Spots | H5: Required Integrations, Setup & Config | I5: Evidence & Deliverables Generated | J5: Complementary Controls & Activities Required | K5: Toolchain Overlaps & Synergies | L5: Residual Toolchain Gaps
A6: SonarQube | B6: Static Application Security Testing (SAST) & Code Quality Platform | C6: Continuous automated static code analysis to detect security vulnerabilities, security hotspots, code smells, and software bugs directly in source code repositories. | D6: CRA-REQ-TECH-01, CRA-REQ-TECH-04, CRA-REQ-TECH-05, CRA-REQ-TECH-06, CRA-REQ-TECH-08, CRA-REQ-TECH-10, CRA-REQ-TECH-11, CRA-REQ-TECH-12, CRA-REQ-VULN-03, CRA-REQ-DOC-01 | E6: Development, Build and Release | F6: Deep pattern matching and AST analysis across 30+ languages; detects OWASP Top 10, SANS/CWE Top 25, hardcoded secrets, SQL injection, path traversal, weak crypto ciphers, and insecure deserialization. Enforces Quality Gates in pull requests. | G6: Lacks dynamic runtime context; cannot detect third-party binary/library vulnerabilities (needs SCA); cannot verify operational host configuration or network encryption; cannot generate SBOMs; cannot prove non-exploitability in running application. | H6: Git repositories (GitHub, GitLab, Bitbucket), CI/CD pipelines (Jenkins, GitHub Actions, GitLab CI), IDE plugins (SonarLint), Quality Gate webhook enforcement. | I6: SonarQube Quality Gate Status Reports; Static Code Vulnerability Scan Summaries; Security Hotspot Review Logs; Technical Debt & Code Cleanliness Metrics (Annex VII dossier inputs). | J6: Coverity (for deep memory safety / safety-critical static analysis); Black Duck / Nexus IQ (for open source dependencies and SBOMs); Penetration testing (for business logic validation). | K6: Overlaps with Coverity on general SAST rules and secret detection; SonarQube is faster and developer-centric, while Coverity provides deeper interprocedural taint analysis. | L6: Zero coverage of third-party open-source SBOMs, deployed configurations, network attack surfaces, incident reporting, or post-market CVE correlation.
A7: Nexus IQ Lifecycle / Nexus IQ CLM | B7: Software Composition Analysis (SCA) & Open Source Governance Platform | C7: Automated identification of open-source software (OSS) components, vulnerable third-party dependencies, license compliance risks, and automated policy enforcement across the SDLC. | D7: CRA-REQ-TECH-01, CRA-REQ-TECH-10, CRA-REQ-VULN-01, CRA-REQ-VULN-02, CRA-REQ-VULN-03, CRA-REQ-MGT-02, CRA-REQ-MGT-04, CRA-REQ-DOC-01 | E7: Development, Build and Release, Maintenance and RUN | F7: Scans package managers (Maven, npm, PyPI, NuGet, Go, etc.) for direct and transitive dependencies; provides Sonatype proprietary vulnerability intelligence and precise CVE mapping; automates pull-request dependency remediation; enforces build break policies. | G7: Analyzes third-party dependencies only; cannot inspect first-party custom source code; cannot analyze compiled C/C++ closed-source firmware without package metadata; cannot assess runtime host hardening or network exposure. | H7: Nexus Repository Manager / Artifactory, CI/CD plugins (Jenkins, GitLab, GitHub Actions), IDE extensions, Jira ticket automation. | I7: Nexus IQ Policy Compliance Reports; Bill of Materials (BoM) exports (CycloneDX / SPDX); Open Source License Risk Audits; Component Vulnerability Triage Logs. | J7: SonarQube / Coverity (for custom source code SAST); Dependency-Track (for continuous post-market SBOM lifecycle tracking); Black Duck (for deep binary snippet matching). | K7: Overlaps directly with Black Duck on open-source SCA and with Dependency-Track on component vulnerability tracking. | L7: Does not perform static analysis of custom code; cannot perform dynamic penetration testing; does not provide statutory CSIRT/ENISA incident reporting.
A8: Penetration Testing | B8: Offensive Security Assessment & Ethical Hacking Activity / Process | C8: Comprehensive manual and automated offensive evaluation of running product builds, deployed appliances, APIs, and cloud backends to identify exploitable security flaws and verify defensive controls. | D8: CRA-REQ-GEN-01, CRA-REQ-TECH-01, CRA-REQ-TECH-02, CRA-REQ-TECH-03, CRA-REQ-TECH-04, CRA-REQ-TECH-05, CRA-REQ-TECH-06, CRA-REQ-TECH-08, CRA-REQ-TECH-09, CRA-REQ-TECH-10, CRA-REQ-TECH-11, CRA-REQ-TECH-12, CRA-REQ-TECH-13, CRA-REQ-VULN-03, CRA-REQ-VULN-07, CRA-REQ-MGT-01, CRA-REQ-DOC-01 | E8: Development, Build and Release, Deployment and Delivery, Maintenance and RUN | F8: Evaluates complex multi-step attack chains, business logic flaws, authentication/authorization bypasses (IDOR/BOLA), cryptographic protocol implementation, anti-tampering, denial-of-service resilience, and physical/logical reset mechanisms. | G8: Point-in-time snapshot assessment; heavily reliant on assessor skill and defined testing scope; cannot continuously monitor post-release without repeated engagements; does not produce machine-readable SBOMs or formal legal DoCs. | H8: Staging/pre-production environments, dedicated testing hardware/appliances, test tenant credentials, threat model documentation inputs. | I8: Formal Penetration Testing Reports (Executive Summary & Technical Vulnerability Findings); Exploitation Proof-of-Concept (PoC) records; Remediation Retest Verification Certificates (Annex VII evidence). | J8: TARA / Threat Modeling (defines penetration testing scope and focus); SAST & SCA (filters baseline bugs prior to pentest); DAST (automates repetitive web/API crawling). | K8: Overlaps with DAST (Burp/ZAP) on web application flaw identification; overlaps with Nessus on exposed service discovery, but with deep exploitation capability. | L8: Cannot replace continuous automated CI/CD gating; does not generate SBOMs; cannot monitor post-market fleet without re-contracting.
A9: Vulnerability Scanning (Nessus / Cyberwatch) | B9: Infrastructure, Network, Host & Container Vulnerability Management Platform | C9: Automated network service discovery, operating system vulnerability scanning, container image inspection, and CIS benchmark / hardening configuration auditing. | D9: CRA-REQ-TECH-01, CRA-REQ-TECH-02, CRA-REQ-TECH-04, CRA-REQ-TECH-05, CRA-REQ-TECH-08, CRA-REQ-TECH-09, CRA-REQ-TECH-10, CRA-REQ-TECH-11, CRA-REQ-TECH-12, CRA-REQ-VULN-03, CRA-REQ-MGT-04, CRA-REQ-DOC-01 | E9: Build and Release, Deployment and Delivery, Maintenance and RUN | F9: Scans exposed network daemons, operating system patch levels, and misconfigurations; audits CIS Benchmark compliance for Linux/Windows; detects default credentials, outdated SSL/TLS ciphers, and unpatched CVEs in host services. Cyberwatch adds agent-based continuous monitoring. | G9: Network/OS level focus; cannot inspect application source code syntax or internal logic (needs SAST); cannot test custom web application business workflows or complex API auth (needs DAST/pentest); does not generate software component SBOMs. | H9: Container registries, hypervisors, cloud infrastructure (AWS/Azure), SIEM platforms, ticketing systems (Jira/ServiceNow). | I9: Host Vulnerability Scan Reports (Nessus XML/PDF); CIS Benchmark Configuration Compliance Scores; Cyberwatch Continuous Monitoring Asset Dashboards; Patch Verification Logs. | J9: SonarQube / Coverity (for source code bugs); Nexus IQ / Black Duck (for third-party library dependencies); Penetration testing (for active exploitation verification). | K9: Overlaps with Burp/ZAP on SSL/TLS and exposed web port detection; overlaps with Black Duck on container base image scanning. | L9: Zero source code visibility; cannot evaluate application-level threat models or generate product SBOMs; cannot draft Annex II documentation.
A10: Data Protection Impact Assessment (DPIA) | B10: Privacy Governance & Regulatory Risk Assessment Process (GDPR Art 35) | C10: Structured legal and technical evaluation of personal data processing operations to identify, assess, and mitigate risks to the rights and freedoms of individuals. | D10: CRA-REQ-GEN-01, CRA-REQ-TECH-04, CRA-REQ-TECH-05, CRA-REQ-TECH-06, CRA-REQ-TECH-07, CRA-REQ-TECH-12, CRA-REQ-TECH-13, CRA-REQ-MGT-01, CRA-REQ-DOC-01 | E10: Presales and Product Planning, Development, Maintenance and RUN | F10: Assesses personal data flows, processing proportionality, legal basis, data minimisation (Annex I(1)(g)), storage limitation, user consent mechanisms, user telemetry opt-out, and right-to-erasure workflows. | G10: Governance and privacy process mandated under GDPR Art 35, NOT a technical testing tool. Does NOT evaluate technical product cybersecurity, network resilience, buffer overflows, or general software vulnerabilities under CRA. | H10: Data Protection Officer (DPO) governance, product requirement specifications, privacy registers, GDPR Art 30 processing records. | I10: Formal DPIA Assessment Dossier (approved and signed by DPO); Data Processing Register; Privacy Architecture Blueprint; User Consent & Telemetry Configuration Specification. | J10: Threat Analysis & Risk Analysis (TARA) (pairs cybersecurity risk with privacy impact); Penetration testing (verifies data access boundary enforcement). | K10: Informs TARA regarding personal data asset values and confidentiality requirements; overlaps conceptually on access control and logging. | L10: Does not replace cybersecurity risk assessment (Art 13(2)); does not test code, networks, or binaries; cannot satisfy CRA technical conformity by itself.
A11: Threat Analysis and Risk Analysis (TARA) | B11: Foundational Security Architecture & Risk Engineering Process (STRIDE / PASTA / IEC 62443) | C11: Systematic engineering methodology to identify operational assets, threat actors, attack vectors, vulnerabilities, and potential security impact, guiding secure-by-design architectural choices. | D11: CRA-REQ-GEN-01, CRA-REQ-TECH-01, CRA-REQ-TECH-02, CRA-REQ-TECH-03, CRA-REQ-TECH-04, CRA-REQ-TECH-05, CRA-REQ-TECH-06, CRA-REQ-TECH-07, CRA-REQ-TECH-08, CRA-REQ-TECH-09, CRA-REQ-TECH-10, CRA-REQ-TECH-11, CRA-REQ-TECH-12, CRA-REQ-TECH-13, CRA-REQ-VULN-03, CRA-REQ-VULN-07, CRA-REQ-MGT-01, CRA-REQ-MGT-02, CRA-REQ-DOC-01, CRA-REQ-CONF-04 | E11: Presales and Product Planning, Development, Maintenance and RUN | F11: Models trust boundaries, external data flows, privileged execution boundaries, and threat scenarios; defines technical security controls before coding begins; provides mandatory Cybersecurity Risk Assessment for Annex VII dossier. | G11: Analytical design and planning activity; does not inspect running code, compile software, or scan binaries; depends on implementation fidelity and must be verified by empirical testing. | H11: Enterprise Architecture tools, threat modeling platforms (IriusRisk, Threat Dragon, Microsoft Threat Modeling Tool), Jira security epic backlogs. | I11: Cybersecurity Risk Assessment Dossier (Annex VII point 1(b)); Threat Model Architecture Diagrams & Attack Trees; Residual Risk Acceptance Register; Security Requirements Traceability Matrix. | J11: Penetration testing (empirically tests threat model assumptions); SAST/DAST/SCA (verifies that mitigation controls are implemented correctly). | K11: Informs penetration testing scoping; pairs with DPIA on data flow risk analysis. | L11: Cannot verify implementation defects without testing tools; does not generate SBOMs; cannot monitor post-market CVE feeds automatically.
A12: Dependency-Track (OWASP) | B12: Continuous Software Bill of Materials (SBOM) Analysis & Vulnerability Platform | C12: Ingests CycloneDX and SPDX SBOMs to provide continuous, real-time post-market vulnerability monitoring, license compliance tracking, and exploitability analysis (VEX). | D12: CRA-REQ-TECH-01, CRA-REQ-VULN-01, CRA-REQ-VULN-02, CRA-REQ-VULN-03, CRA-REQ-MGT-02, CRA-REQ-MGT-04, CRA-REQ-DOC-01, CRA-REQ-DOC-04 | E12: Build and Release, Deployment and Delivery, Maintenance and RUN | F12: Ingests standard SBOMs; continuously correlates component inventories against NVD, GitHub Advisories, OSV, and Sonatype OSS Index; tracks portfolio-wide vulnerability metrics; generates and ingests VEX (Vulnerability Exploitability eXchange) records; REST API-first architecture. | G12: Does not generate SBOMs from source code directly (relies on build-time tools like cdxgen/syft); does not perform SAST or DAST; does not scan custom code or running networks. | H12: CI/CD pipelines via REST API, SBOM generation plugins (cdxgen, Maven/Gradle/npm plugins), DefectDojo, Jira/ServiceNow webhooks, NVD/OSV feeds. | I12: Centralized Portfolio SBOM Inventory; Real-Time Vulnerability Alert Feeds; Exportable Machine-Readable SBOMs (CycloneDX JSON); VEX Exploitability Statements; Post-Market Triage Logs. | J12: Nexus IQ / Black Duck (generates SBOMs during build); SonarQube / Coverity (covers custom code); PSIRT triage runbooks. | K12: Overlaps with Black Duck and Nexus IQ on post-build vulnerability tracking and CVE correlation; Dependency-Track excels as an independent, vendor-neutral SBOM manager. | L12: Does not scan custom code; cannot test runtime interfaces or configurations; does not handle statutory incident reporting to CSIRTs/ENISA.
A13: Black Duck (Synopsys / Black Duck Software) | B13: Enterprise Software Composition Analysis (SCA) & Binary Analysis Platform | C13: Comprehensive open-source discovery, deep snippet matching, binary analysis without source code, SBOM generation, license governance, and continuous CVE tracking. | D13: CRA-REQ-TECH-01, CRA-REQ-TECH-10, CRA-REQ-VULN-01, CRA-REQ-VULN-02, CRA-REQ-VULN-03, CRA-REQ-MGT-02, CRA-REQ-MGT-04, CRA-REQ-DOC-01, CRA-REQ-DOC-04 | E13: Development, Build and Release, Deployment and Delivery, Maintenance and RUN | F13: Deep signature and code snippet scanning to detect hidden/copied open source; binary analysis identifying components in compiled firmware/executables; enterprise SBOM generation (SPDX, CycloneDX); automated policy gates; continuous post-release CVE alerts. | G13: Focuses on third-party and open source components; cannot detect custom business logic flaws in proprietary source code (needs Coverity); cannot verify dynamic web endpoints (needs DAST/pentest). | H13: CI/CD pipelines (Detect wrapper), binary repositories (Artifactory), container registries, enterprise ERP/procurement systems, Jira. | I13: Black Duck Open Source Audit Reports; Formal SBOM Exports (SPDX 2.3 / CycloneDX 1.6); Open Source License Risk Audits; Component Vulnerability Triage Reports. | J13: Coverity (pairs as Synopsys Polaris suite for complete code + component coverage); Penetration testing (for runtime verification); TARA (for threat modeling). | K13: Overlaps directly with Nexus IQ CLM on open source SCA; overlaps with Dependency-Track on SBOM tracking; Black Duck provides superior binary and snippet matching. | L13: Does not analyze custom proprietary code defects; cannot perform dynamic penetration testing; cannot execute statutory CSIRT notifications.
A14: Coverity (Synopsys Coverity) | B14: Enterprise Deep Static Application Security Testing (SAST) Platform | C14: Industrial-strength interprocedural static analysis detecting complex memory corruption, concurrency race conditions, taint-flow security flaws, and coding defects across enterprise and embedded codebases. | D14: CRA-REQ-TECH-01, CRA-REQ-TECH-04, CRA-REQ-TECH-05, CRA-REQ-TECH-06, CRA-REQ-TECH-08, CRA-REQ-TECH-10, CRA-REQ-TECH-11, CRA-REQ-TECH-12, CRA-REQ-VULN-03, CRA-REQ-DOC-01 | E14: Development, Build and Release | F14: Deep interprocedural control and data flow analysis; premier detection of buffer overflows, use-after-free, double free, integer overflows, memory leaks, null pointer dereferences in C/C++; taint analysis for web frameworks (Java, C#, Go, Python); MISRA, CERT, and OWASP compliance auditing. | G14: Resource-intensive compilation-based analysis; does not inspect third-party open-source dependency licenses (needs Black Duck); cannot evaluate running services, network protocols, or host configurations. | H14: Compiler toolchains (GCC, Clang, MSVC, embedded cross-compilers), CI/CD pipelines (Jenkins, GitLab, GitHub Actions), IDE plugins (Fast Desktop), Coverity Connect dashboard. | I14: Coverity Static Analysis Quality & Security Reports; Memory Safety Defect Verification Logs; MISRA / CERT C Compliance Reports; Pre-Release Static Audit Sign-offs. | J14: Black Duck (for open-source SCA and SBOMs); SonarQube (for rapid day-to-day developer PR checks); Penetration testing (for dynamic business logic attacks). | K14: Overlaps with SonarQube on source code scanning; Coverity provides far deeper interprocedural path analysis and memory safety verification for compiled languages. | L14: Zero SCA / SBOM generation capability; cannot test runtime environments or infrastructure; does not handle post-market fleet monitoring.
A15: OWASP ZAP / Burp Suite | B15: Dynamic Application Security Testing (DAST) & Interactive API Security Tool | C15: Automated and interactive black-box and gray-box dynamic security testing of running web applications, REST/GraphQL APIs, and WebSocket communication channels. | D15: CRA-REQ-TECH-01, CRA-REQ-TECH-02, CRA-REQ-TECH-04, CRA-REQ-TECH-05, CRA-REQ-TECH-06, CRA-REQ-TECH-08, CRA-REQ-TECH-09, CRA-REQ-TECH-10, CRA-REQ-VULN-03, CRA-REQ-DOC-01 | E15: Development, Build and Release, Deployment and Delivery | F15: Active/passive scanning of running endpoints; intercepts and manipulates HTTP/S traffic; identifies injection flaws (SQLi, XSS, SSRF), authentication/session bypasses, insecure direct object references (IDOR), security header misconfigurations, and API rate limiting weaknesses. | G15: Requires a running, testable target instance; limited visibility into internal source code logic, database structures, or memory state; cannot scan closed-source binaries or generate SBOMs; cannot monitor post-market fleets continuously. | H15: Staging environments, OpenAPI / Swagger specifications, Postman collections, CI/CD pipelines (ZAP automation framework), DefectDojo, Jira. | I15: DAST Automated Scan Reports (HTML/JSON); Burp Suite Professional / Enterprise Assessment Dossiers; API Security Vulnerability Logs; HTTP Security Header Audit Records. | J15: SonarQube / Coverity (SAST finds internal code flaws while DAST finds exposed endpoint flaws); Penetration testing (human tester uses Burp for complex exploits). | K15: Overlaps with manual penetration testing (Burp is the primary tool used by pentest consultants); overlaps with Nessus on web server header checks. | L15: Cannot inspect source code or firmware internals; cannot generate SBOMs; cannot verify legal compliance or incident reporting.
A18: TABLE B: QUANTITATIVE TOOL COVERAGE METRICS & STATISTICAL SUMMARY (EXCEL FORMULAS)
A19: Methodology: Evaluated across all 43 traceable CRA requirements. Excludes Non-Applicable requirements from denominator. Formulas dynamically reference 'CRA Requirements Matrix'.
A20: Tool / Activity Name | B20: Total Applicable Reqs (Denominator) | C20: Full Coverage Count | D20: Full Coverage % | E20: Partial Coverage Count | F20: Partial Coverage % | G20: None Coverage Count | H20: None Coverage % | I20: Direct Technical Contribution % | J20: Primary Lifecycle Focus | K20: Operational Methodology & Scoping Assumptions
A21: SonarQube | B21: 43 | C21: =COUNTIF('CRA Requirements Matrix'!Q$4:Q$46, "Full") | D21: =C21/B21 | E21: =COUNTIF('CRA Requirements Matrix'!Q$4:Q$46, "Partial") | F21: =E21/B21 | G21: =COUNTIF('CRA Requirements Matrix'!Q$4:Q$46, "None") | H21: =G21/B21 | I21: =(C21+E21)/B21 | J21: Development, Build and Release | K21: Automated code quality & SAST gating in CI/CD for first-party code.
A22: Nexus IQ Lifecycle / CLM | B22: 43 | C22: =COUNTIF('CRA Requirements Matrix'!R$4:R$46, "Full") | D22: =C22/B22 | E22: =COUNTIF('CRA Requirements Matrix'!R$4:R$46, "Partial") | F22: =E22/B22 | G22: =COUNTIF('CRA Requirements Matrix'!R$4:R$46, "None") | H22: =G22/B22 | I22: =(C22+E22)/B22 | J22: Development, Build, RUN | K22: SCA package manager scanning; policy enforcement for open source libraries.
A23: Penetration Testing | B23: 43 | C23: =COUNTIF('CRA Requirements Matrix'!S$4:S$46, "Full") | D23: =C23/B23 | E23: =COUNTIF('CRA Requirements Matrix'!S$4:S$46, "Partial") | F23: =E23/B23 | G23: =COUNTIF('CRA Requirements Matrix'!S$4:S$46, "None") | H23: =G23/B23 | I23: =(C23+E23)/B23 | J23: Development, Build, RUN | K23: Offensive security verification of running product builds & APIs.
A24: Vulnerability Scanning (Nessus / Cyberwatch) | B24: 43 | C24: =COUNTIF('CRA Requirements Matrix'!T$4:T$46, "Full") | D24: =C24/B24 | E24: =COUNTIF('CRA Requirements Matrix'!T$4:T$46, "Partial") | F24: =E24/B24 | G24: =COUNTIF('CRA Requirements Matrix'!T$4:T$46, "None") | H24: =G24/B24 | I24: =(C24+E24)/B24 | J24: Build, Deployment, RUN | K24: Infrastructure, OS, daemon, and CIS configuration hardening auditing.
A25: Data Protection Impact Assessment (DPIA) | B25: 43 | C25: =COUNTIF('CRA Requirements Matrix'!U$4:U$46, "Full") | D25: =C25/B25 | E25: =COUNTIF('CRA Requirements Matrix'!U$4:U$46, "Partial") | F25: =E25/B25 | G25: =COUNTIF('CRA Requirements Matrix'!U$4:U$46, "None") | H25: =G25/B25 | I25: =(C25+E25)/B25 | J25: Planning, Development | K25: GDPR Art 35 privacy assessment; addresses data minimisation & rights.
A26: Threat Analysis & Risk Analysis (TARA) | B26: 43 | C26: =COUNTIF('CRA Requirements Matrix'!V$4:V$46, "Full") | D26: =C26/B26 | E26: =COUNTIF('CRA Requirements Matrix'!V$4:V$46, "Partial") | F26: =E26/B26 | G26: =COUNTIF('CRA Requirements Matrix'!V$4:V$46, "None") | H26: =G26/B26 | I26: =(C26+E26)/B26 | J26: Planning, Design, RUN | K26: Foundational engineering process deriving Annex VII risk assessment.
A27: Dependency-Track | B27: 43 | C27: =COUNTIF('CRA Requirements Matrix'!W$4:W$46, "Full") | D27: =C27/B27 | E27: =COUNTIF('CRA Requirements Matrix'!W$4:W$46, "Partial") | F27: =E27/B27 | G27: =COUNTIF('CRA Requirements Matrix'!W$4:W$46, "None") | H27: =G27/B27 | I27: =(C27+E27)/B27 | J27: Build, Deployment, RUN | K27: Continuous SBOM ingestion & post-market vulnerability monitoring.
